Workbook

Sheet Resumo Pagamento
A1: Data de Pagamento | B1: TOTAL CENTRO DE DISTRIBUICAO INTEGRADA LTDA - 12.460.301/0001-87 | C1: FRUGIS REPRESENTACOES LTDA - 11.989.186/0001-70 | D1: Líquido (R$) - FINAL | E1: Competência (mês anterior ao pagto) | F1: Valor original da base (R$) | G1: Extrato real / meu cálculo (R$) | H1: Diferença (original − extrato) | I1: O que foi usado na coluna D | J1: Origem | K1: Ano pagto | L1: Mês do pagamento | M1: Fator IPCA até a referência | N1: Valor corrigido IPCA (R$)
A2: 15/02/2001 | B2: TOTAL CENTRO DE DISTRIBUICAO INTEGRADA LTDA - 12.460.301/0001-87 | C2: FRUGIS REPRESENTACOES LTDA - 11.989.186/0001-70 | D2: =F2 | E2: 01/2001 | F2: 240.76365 | I2: Mantido valor original da base (sem extrato) | J2: — | K2: =VALUE(RIGHT(A2,4)) | L2: =DATE(VALUE(RIGHT(A2,4)),VALUE(MID(A2,4,2)),1) | M2: =INDEX(IPCA!$D$5:$D$313,MATCH(Distrato!$B$3,IPCA!$A$5:$A$313,0))/INDEX(IPCA!$D$5:$D$313,MATCH(DATE(YEAR(L2),MONTH(L2)-1,1),IPCA!$A$5:$A$313,0)) | N2: =IF(L2>Distrato!$B$3,D2,D2*M2)
A3: 15/03/2001 | B3: TOTAL CENTRO DE DISTRIBUICAO INTEGRADA LTDA - 12.460.301/0001-87 | C3: FRUGIS REPRESENTACOES LTDA - 11.989.186/0001-70 | D3: =F3 | E3: 02/2001 | F3: 235.32596 | I3: Mantido valor original da base (sem extrato) | J3: — | K3: =VALUE(RIGHT(A3,4)) | L3: =DATE(VALUE(RIGHT(A3,4)),VALUE(MID(A3,4,2)),1) | M3: =INDEX(IPCA!$D$5:$D$313,MATCH(Distrato!$B$3,IPCA!$A$5:$A$313,0))/INDEX(IPCA!$D$5:$D$313,MATCH(DATE(YEAR(L3),MONTH(L3)-1,1),IPCA!$A$5:$A$313,0)) | N3: =IF(L3>Distrato!$B$3,D3,D3*M3)
A4: 15/04/2001 | B4: TOTAL CENTRO DE DISTRIBUICAO INTEGRADA LTDA - 12.460.301/0001-87 | C4: FRUGIS REPRESENTACOES LTDA - 11.989.186/0001-70 | D4: =F4 | E4: 03/2001 | F4: 235.32566 | I4: Mantido valor original da base (sem extrato) | J4: — | K4: =VALUE(RIGHT(A4,4)) | L4: =DATE(VALUE(RIGHT(A4,4)),VALUE(MID(A4,4,2)),1) | M4: =INDEX(IPCA!$D$5:$D$313,MATCH(Distrato!$B$3,IPCA!$A$5:$A$313,0))/INDEX(IPCA!$D$5:$D$313,MATCH(DATE(YEAR(L4),MONTH(L4)-1,1),IPCA!$A$5:$A$313,0)) | N4: =IF(L4>Distrato!$B$3,D4,D4*M4)
A5: 15/05/2001 | B5: TOTAL CENTRO DE DISTRIBUICAO INTEGRADA LTDA - 12.460.301/0001-87 | C5: FRUGIS REPRESENTACOES LTDA - 11.989.186/0001-70 | D5: =F5 | E5: 04/2001 | F5: 234.12285 | I5: Mantido valor original da base (sem extrato) | J5: — | K5: =VALUE(RIGHT(A5,4)) | L5: =DATE(VALUE(RIGHT(A5,4)),VALUE(MID(A5,4,2)),1) | M5: =INDEX(IPCA!$D$5:$D$313,MATCH(Distrato!$B$3,IPCA!$A$5:$A$313,0))/INDEX(IPCA!$D$5:$D$313,MATCH(DATE(YEAR(L5),MONTH(L5)-1,1),IPCA!$A$5:$A$313,0)) | N5: =IF(L5>Distrato!$B$3,D5,D5*M5)
A6: 15/06/2001 | B6: TOTAL CENTRO DE DISTRIBUICAO INTEGRADA LTDA - 12.460.301/0001-87 | C6: FRUGIS REPRESENTACOES LTDA - 11.989.186/0001-70 | D6: =F6 | E6: 05/2001 | F6: 244.05003 | I6: Mantido valor original da base (sem extrato) | J6: — | K6: =VALUE(RIGHT(A6,4)) | L6: =DATE(VALUE(RIGHT(A6,4)),VALUE(MID(A6,4,2)),1) | M6: =INDEX(IPCA!$D$5:$D$313,MATCH(Distrato!$B$3,IPCA!$A$5:$A$313,0))/INDEX(IPCA!$D$5:$D$313,MATCH(DATE(YEAR(L6),MONTH(L6)-1,1),IPCA!$A$5:$A$313,0)) | N6: =IF(L6>Distrato!$B$3,D6,D6*M6)
A7: 15/07/2001 | B7: TOTAL CENTRO DE DISTRIBUICAO INTEGRADA LTDA - 12.460.301/0001-87 | C7: FRUGIS REPRESENTACOES LTDA - 11.989.186/0001-70 | D7: =F7 | E7: 06/2001 | F7: 240.79383 | I7: Mantido valor original da base (sem extrato) | J7: — | K7: =VALUE(RIGHT(A7,4)) | L7: =DATE(VALUE(RIGHT(A7,4)),VALUE(MID(A7,4,2)),1) | M7: =INDEX(IPCA!$D$5:$D$313,MATCH(Distrato!$B$3,IPCA!$A$5:$A$313,0))/INDEX(IPCA!$D$5:$D$313,MATCH(DATE(YEAR(L7),MONTH(L7)-1,1),IPCA!$A$5:$A$313,0)) | N7: =IF(L7>Distrato!$B$3,D7,D7*M7)
A8: 15/08/2001 | B8: TOTAL CENTRO DE DISTRIBUICAO INTEGRADA LTDA - 12.460.301/0001-87 | C8: FRUGIS REPRESENTACOES LTDA - 11.989.186/0001-70 | D8: =F8 | E8: 07/2001 | F8: 242.10777 | I8: Mantido valor original da base (sem extrato) | J8: — | K8: =VALUE(RIGHT(A8,4)) | L8: =DATE(VALUE(RIGHT(A8,4)),VALUE(MID(A8,4,2)),1) | M8: =INDEX(IPCA!$D$5:$D$313,MATCH(Distrato!$B$3,IPCA!$A$5:$A$313,0))/INDEX(IPCA!$D$5:$D$313,MATCH(DATE(YEAR(L8),MONTH(L8)-1,1),IPCA!$A$5:$A$313,0)) | N8: =IF(L8>Distrato!$B$3,D8,D8*M8)
A9: 15/09/2001 | B9: TOTAL CENTRO DE DISTRIBUICAO INTEGRADA LTDA - 12.460.301/0001-87 | C9: FRUGIS REPRESENTACOES LTDA - 11.989.186/0001-70 | D9: =F9 | E9: 08/2001 | F9: 233.66219 | I9: Mantido valor original da base (sem extrato) | J9: — | K9: =VALUE(RIGHT(A9,4)) | L9: =DATE(VALUE(RIGHT(A9,4)),VALUE(MID(A9,4,2)),1) | M9: =INDEX(IPCA!$D$5:$D$313,MATCH(Distrato!$B$3,IPCA!$A$5:$A$313,0))/INDEX(IPCA!$D$5:$D$313,MATCH(DATE(YEAR(L9),MONTH(L9)-1,1),IPCA!$A$5:$A$313,0)) | N9: =IF(L9>Distrato!$B$3,D9,D9*M9)
A10: 15/10/2001 | B10: TOTAL CENTRO DE DISTRIBUICAO INTEGRADA LTDA - 12.460.301/0001-87 | C10: FRUGIS REPRESENTACOES LTDA - 11.989.186/0001-70 | D10: =F10 | E10: 09/2001 | F10: 245.32437 | I10: Mantido valor original da base (sem extrato) | J10: — | K10: =VALUE(RIGHT(A10,4)) | L10: =DATE(VALUE(RIGHT(A10,4)),VALUE(MID(A10,4,2)),1) | M10: =INDEX(IPCA!$D$5:$D$313,MATCH(Distrato!$B$3,IPCA!$A$5:$A$313,0))/INDEX(IPCA!$D$5:$D$313,MATCH(DATE(YEAR(L10),MONTH(L10)-1,1),IPCA!$A$5:$A$313,0)) | N10: =IF(L10>Distrato!$B$3,D10,D10*M10)
A11: 15/11/2001 | B11: TOTAL CENTRO DE DISTRIBUICAO INTEGRADA LTDA - 12.460.301/0001-87 | C11: FRUGIS REPRESENTACOES LTDA - 11.989.186/0001-70 | D11: =F11 | E11: 10/2001 | F11: 243.63562 | I11: Mantido valor original da base (sem extrato) | J11: — | K11: =VALUE(RIGHT(A11,4)) | L11: =DATE(VALUE(RIGHT(A11,4)),VALUE(MID(A11,4,2)),1) | M11: =INDEX(IPCA!$D$5:$D$313,MATCH(Distrato!$B$3,IPCA!$A$5:$A$313,0))/INDEX(IPCA!$D$5:$D$313,MATCH(DATE(YEAR(L11),MONTH(L11)-1,1),IPCA!$A$5:$A$313,0)) | N11: =IF(L11>Distrato!$B$3,D11,D11*M11)
A12: 15/12/2001 | B12: TOTAL CENTRO DE DISTRIBUICAO INTEGRADA LTDA - 12.460.301/0001-87 | C12: FRUGIS REPRESENTACOES LTDA - 11.989.186/0001-70 | D12: =F12 | E12: 11/2001 | F12: 236.01784 | I12: Mantido valor original da base (sem extrato) | J12: — | K12: =VALUE(RIGHT(A12,4)) | L12: =DATE(VALUE(RIGHT(A12,4)),VALUE(MID(A12,4,2)),1) | M12: =INDEX(IPCA!$D$5:$D$313,MATCH(Distrato!$B$3,IPCA!$A$5:$A$313,0))/INDEX(IPCA!$D$5:$D$313,MATCH(DATE(YEAR(L12),MONTH(L12)-1,1),IPCA!$A$5:$A$313,0)) | N12: =IF(L12>Distrato!$B$3,D12,D12*M12)
A13: 15/01/2002 | B13: TOTAL CENTRO DE DISTRIBUICAO INTEGRADA LTDA - 12.460.301/0001-87 | C13: FRUGIS REPRESENTACOES LTDA - 11.989.186/0001-70 | D13: =F13 | E13: 12/2001 | F13: 235.64298 | I13: Mantido valor original da base (sem extrato) | J13: — | K13: =VALUE(RIGHT(A13,4)) | L13: =DATE(VALUE(RIGHT(A13,4)),VALUE(MID(A13,4,2)),1) | M13: =INDEX(IPCA!$D$5:$D$313,MATCH(Distrato!$B$3,IPCA!$A$5:$A$313,0))/INDEX(IPCA!$D$5:$D$313,MATCH(DATE(YEAR(L13),MONTH(L13)-1,1),IPCA!$A$5:$A$313,0)) | N13: =IF(L13>Distrato!$B$3,D13,D13*M13)
... A49: 15/01/2005 | B49: TOTAL CENTRO DE DISTRIBUICAO INTEGRADA LTDA - 12.460.301/0001-87 | C49: FRUGIS REPRESENTACOES LTDA - 11.989.186/0001-70 | D49: =F49 | E49: 12/2004 | F49: 324.87539 | I49: Mantido valor original da base (sem extrato) | J49: — | K49: =VALUE(RIGHT(A49,4)) | L49: =DATE(VALUE(RIGHT(A49,4)),VALUE(MID(A49,4,2)),1) | M49: =INDEX(IPCA!$D$5:$D$313,MATCH(Distrato!$B$3,IPCA!$A$5:$A$313,0))/INDEX(IPCA!$D$5:$D$313,MATCH(DATE(YEAR(L49),MONTH(L49)-1,1),IPCA!$A$5:$A$313,0)) | N49: =IF(L49>Distrato!$B$3,D49,D49*M49)
A50: 15/02/2005 | B50: TOTAL CENTRO DE DISTRIBUICAO INTEGRADA LTDA - 12.460.301/0001-87 | C50: FRUGIS REPRESENTACOES LTDA - 11.989.186/0001-70 | D50: =G50 | E50: 01/2005 | F50: 602.2 | G50: 602.2 | H50: =F50-G50 | I50: Extrato real | J50: Extrato conta corrente - Tenda | K50: =VALUE(RIGHT(A50,4)) | L50: =DATE(VALUE(RIGHT(A50,4)),VALUE(MID(A50,4,2)),1) | M50: =INDEX(IPCA!$D$5:$D$313,MATCH(Distrato!$B$3,IPCA!$A$5:$A$313,0))/INDEX(IPCA!$D$5:$D$313,MATCH(DATE(YEAR(L50),MONTH(L50)-1,1),IPCA!$A$5:$A$313,0)) | N50: =IF(L50>Distrato!$B$3,D50,D50*M50)
A51: 15/03/2005 | B51: TOTAL CENTRO DE DISTRIBUICAO INTEGRADA LTDA - 12.460.301/0001-87 | C51: FRUGIS REPRESENTACOES LTDA - 11.989.186/0001-70 | D51: =G51 | E51: 02/2005 | F51: 217.38 | G51: 217.38 | H51: =F51-G51 | I51: Extrato real | J51: Extrato conta corrente - Tenda | K51: =VALUE(RIGHT(A51,4)) | L51: =DATE(VALUE(RIGHT(A51,4)),VALUE(MID(A51,4,2)),1) | M51: =INDEX(IPCA!$D$5:$D$313,MATCH(Distrato!$B$3,IPCA!$A$5:$A$313,0))/INDEX(IPCA!$D$5:$D$313,MATCH(DATE(YEAR(L51),MONTH(L51)-1,1),IPCA!$A$5:$A$313,0)) | N51: =IF(L51>Distrato!$B$3,D51,D51*M51)
A52: 15/04/2005 | B52: TOTAL CENTRO DE DISTRIBUICAO INTEGRADA LTDA - 12.460.301/0001-87 | C52: FRUGIS REPRESENTACOES LTDA - 11.989.186/0001-70 | D52: =G52 | E52: 03/2005 | F52: 517.99 | G52: 517.99 | H52: =F52-G52 | I52: Extrato real | J52: Extrato conta corrente - Tenda | K52: =VALUE(RIGHT(A52,4)) | L52: =DATE(VALUE(RIGHT(A52,4)),VALUE(MID(A52,4,2)),1) | M52: =INDEX(IPCA!$D$5:$D$313,MATCH(Distrato!$B$3,IPCA!$A$5:$A$313,0))/INDEX(IPCA!$D$5:$D$313,MATCH(DATE(YEAR(L52),MONTH(L52)-1,1),IPCA!$A$5:$A$313,0)) | N52: =IF(L52>Distrato!$B$3,D52,D52*M52)
A53: 15/05/2005 | B53: TOTAL CENTRO DE DISTRIBUICAO INTEGRADA LTDA - 12.460.301/0001-87 | C53: FRUGIS REPRESENTACOES LTDA - 11.989.186/0001-70 | D53: =G53 | E53: 04/2005 | F53: 226.59 | G53: 226.59 | H53: =F53-G53 | I53: Extrato real | J53: Extrato conta corrente - Tenda | K53: =VALUE(RIGHT(A53,4)) | L53: =DATE(VALUE(RIGHT(A53,4)),VALUE(MID(A53,4,2)),1) | M53: =INDEX(IPCA!$D$5:$D$313,MATCH(Distrato!$B$3,IPCA!$A$5:$A$313,0))/INDEX(IPCA!$D$5:$D$313,MATCH(DATE(YEAR(L53),MONTH(L53)-1,1),IPCA!$A$5:$A$313,0)) | N53: =IF(L53>Distrato!$B$3,D53,D53*M53)
A54: 15/06/2005 | B54: TOTAL CENTRO DE DISTRIBUICAO INTEGRADA LTDA - 12.460.301/0001-87 | C54: FRUGIS REPRESENTACOES LTDA - 11.989.186/0001-70 | D54: =G54 | E54: 05/2005 | F54: 315.4 | G54: 315.4 | H54: =F54-G54 | I54: Extrato real | J54: Extrato conta corrente - Tenda | K54: =VALUE(RIGHT(A54,4)) | L54: =DATE(VALUE(RIGHT(A54,4)),VALUE(MID(A54,4,2)),1) | M54: =INDEX(IPCA!$D$5:$D$313,MATCH(Distrato!$B$3,IPCA!$A$5:$A$313,0))/INDEX(IPCA!$D$5:$D$313,MATCH(DATE(YEAR(L54),MONTH(L54)-1,1),IPCA!$A$5:$A$313,0)) | N54: =IF(L54>Distrato!$B$3,D54,D54*M54)
A55: 15/07/2005 | B55: TOTAL CENTRO DE DISTRIBUICAO INTEGRADA LTDA - 12.460.301/0001-87 | C55: FRUGIS REPRESENTACOES LTDA - 11.989.186/0001-70 | D55: =G55 | E55: 06/2005 | F55: 368.97 | G55: 368.97 | H55: =F55-G55 | I55: Extrato real | J55: Extrato conta corrente - Tenda | K55: =VALUE(RIGHT(A55,4)) | L55: =DATE(VALUE(RIGHT(A55,4)),VALUE(MID(A55,4,2)),1) | M55: =INDEX(IPCA!$D$5:$D$313,MATCH(Distrato!$B$3,IPCA!$A$5:$A$313,0))/INDEX(IPCA!$D$5:$D$313,MATCH(DATE(YEAR(L55),MONTH(L55)-1,1),IPCA!$A$5:$A$313,0)) | N55: =IF(L55>Distrato!$B$3,D55,D55*M55)
A56: 15/08/2005 | B56: TOTAL CENTRO DE DISTRIBUICAO INTEGRADA LTDA - 12.460.301/0001-87 | C56: FRUGIS REPRESENTACOES LTDA - 11.989.186/0001-70 | D56: =G56 | E56: 07/2005 | F56: 163.91 | G56: 163.91 | H56: =F56-G56 | I56: Extrato real | J56: Extrato conta corrente - Tenda | K56: =VALUE(RIGHT(A56,4)) | L56: =DATE(VALUE(RIGHT(A56,4)),VALUE(MID(A56,4,2)),1) | M56: =INDEX(IPCA!$D$5:$D$313,MATCH(Distrato!$B$3,IPCA!$A$5:$A$313,0))/INDEX(IPCA!$D$5:$D$313,MATCH(DATE(YEAR(L56),MONTH(L56)-1,1),IPCA!$A$5:$A$313,0)) | N56: =IF(L56>Distrato!$B$3,D56,D56*M56)
A57: 15/09/2005 | B57: TOTAL CENTRO DE DISTRIBUICAO INTEGRADA LTDA - 12.460.301/0001-87 | C57: FRUGIS REPRESENTACOES LTDA - 11.989.186/0001-70 | D57: =G57 | E57: 08/2005 | F57: 295.13 | G57: 295.13 | H57: =F57-G57 | I57: Extrato real | J57: Extrato conta corrente - Tenda | K57: =VALUE(RIGHT(A57,4)) | L57: =DATE(VALUE(RIGHT(A57,4)),VALUE(MID(A57,4,2)),1) | M57: =INDEX(IPCA!$D$5:$D$313,MATCH(Distrato!$B$3,IPCA!$A$5:$A$313,0))/INDEX(IPCA!$D$5:$D$313,MATCH(DATE(YEAR(L57),MONTH(L57)-1,1),IPCA!$A$5:$A$313,0)) | N57: =IF(L57>Distrato!$B$3,D57,D57*M57)
A58: 15/10/2005 | B58: TOTAL CENTRO DE DISTRIBUICAO INTEGRADA LTDA - 12.460.301/0001-87 | C58: FRUGIS REPRESENTACOES LTDA - 11.989.186/0001-70 | D58: =G58 | E58: 09/2005 | F58: 314.69 | G58: 314.69 | H58: =F58-G58 | I58: Extrato real | J58: Extrato conta corrente - Tenda | K58: =VALUE(RIGHT(A58,4)) | L58: =DATE(VALUE(RIGHT(A58,4)),VALUE(MID(A58,4,2)),1) | M58: =INDEX(IPCA!$D$5:$D$313,MATCH(Distrato!$B$3,IPCA!$A$5:$A$313,0))/INDEX(IPCA!$D$5:$D$313,MATCH(DATE(YEAR(L58),MONTH(L58)-1,1),IPCA!$A$5:$A$313,0)) | N58: =IF(L58>Distrato!$B$3,D58,D58*M58)
A59: 15/11/2005 | B59: TOTAL CENTRO DE DISTRIBUICAO INTEGRADA LTDA - 12.460.301/0001-87 | C59: FRUGIS REPRESENTACOES LTDA - 11.989.186/0001-70 | D59: =G59 | E59: 10/2005 | F59: 258.22 | G59: 258.22 | H59: =F59-G59 | I59: Extrato real | J59: Extrato conta corrente - Tenda | K59: =VALUE(RIGHT(A59,4)) | L59: =DATE(VALUE(RIGHT(A59,4)),VALUE(MID(A59,4,2)),1) | M59: =INDEX(IPCA!$D$5:$D$313,MATCH(Distrato!$B$3,IPCA!$A$5:$A$313,0))/INDEX(IPCA!$D$5:$D$313,MATCH(DATE(YEAR(L59),MONTH(L59)-1,1),IPCA!$A$5:$A$313,0)) | N59: =IF(L59>Distrato!$B$3,D59,D59*M59)
A60: 15/12/2005 | B60: TOTAL CENTRO DE DISTRIBUICAO INTEGRADA LTDA - 12.460.301/0001-87 | C60: FRUGIS REPRESENTACOES LTDA - 11.989.186/0001-70 | D60: =G60 | E60: 11/2005 | F60: 253.85 | G60: 253.85 | H60: =F60-G60 | I60: Extrato real | J60: Extrato conta corrente - Tenda | K60: =VALUE(RIGHT(A60,4)) | L60: =DATE(VALUE(RIGHT(A60,4)),VALUE(MID(A60,4,2)),1) | M60: =INDEX(IPCA!$D$5:$D$313,MATCH(Distrato!$B$3,IPCA!$A$5:$A$313,0))/INDEX(IPCA!$D$5:$D$313,MATCH(DATE(YEAR(L60),MONTH(L60)-1,1),IPCA!$A$5:$A$313,0)) | N60: =IF(L60>Distrato!$B$3,D60,D60*M60)
A61: 15/01/2006 | B61: TOTAL CENTRO DE DISTRIBUICAO INTEGRADA LTDA - 12.460.301/0001-87 | C61: FRUGIS REPRESENTACOES LTDA - 11.989.186/0001-70 | D61: =G61 | E61: 12/2005 | F61: 666.85 | G61: 666.85 | H61: =F61-G61 | I61: Extrato real | J61: Extrato conta corrente - Tenda | K61: =VALUE(RIGHT(A61,4)) | L61: =DATE(VALUE(RIGHT(A61,4)),VALUE(MID(A61,4,2)),1) | M61: =INDEX(IPCA!$D$5:$D$313,MATCH(Distrato!$B$3,IPCA!$A$5:$A$313,0))/INDEX(IPCA!$D$5:$D$313,MATCH(DATE(YEAR(L61),MONTH(L61)-1,1),IPCA!$A$5:$A$313,0)) | N61: =IF(L61>Distrato!$B$3,D61,D61*M61)
... A118: 15/10/2010 | B118: TOTAL CENTRO DE DISTRIBUICAO INTEGRADA LTDA - 12.460.301/0001-87 | C118: FRUGIS REPRESENTACOES LTDA - 11.989.186/0001-70 | D118: =G118 | E118: 09/2010 | F118: 1832.95 | G118: 1832.95 | H118: =F118-G118 | I118: Extrato real | J118: Extrato conta corrente - Tenda | K118: =VALUE(RIGHT(A118,4)) | L118: =DATE(VALUE(RIGHT(A118,4)),VALUE(MID(A118,4,2)),1) | M118: =INDEX(IPCA!$D$5:$D$313,MATCH(Distrato!$B$3,IPCA!$A$5:$A$313,0))/INDEX(IPCA!$D$5:$D$313,MATCH(DATE(YEAR(L118),MONTH(L118)-1,1),IPCA!$A$5:$A$313,0)) | N118: =IF(L118>Distrato!$B$3,D118,D118*M118)
A119: 15/11/2010 | B119: TOTAL CENTRO DE DISTRIBUICAO INTEGRADA LTDA - 12.460.301/0001-87 | C119: FRUGIS REPRESENTACOES LTDA - 11.989.186/0001-70 | D119: =F119 | E119: 10/2010 | F119: 2479.2133 | G119: 2440.52 | H119: =F119-G119 | I119: Mantido valor original da base (sem extrato) | J119: ESTIMADO (média c/ variação) | K119: =VALUE(RIGHT(A119,4)) | L119: =DATE(VALUE(RIGHT(A119,4)),VALUE(MID(A119,4,2)),1) | M119: =INDEX(IPCA!$D$5:$D$313,MATCH(Distrato!$B$3,IPCA!$A$5:$A$313,0))/INDEX(IPCA!$D$5:$D$313,MATCH(DATE(YEAR(L119),MONTH(L119)-1,1),IPCA!$A$5:$A$313,0)) | N119: =IF(L119>Distrato!$B$3,D119,D119*M119)
A120: 15/12/2010 | B120: TOTAL CENTRO DE DISTRIBUICAO INTEGRADA LTDA - 12.460.301/0001-87 | C120: FRUGIS REPRESENTACOES LTDA - 11.989.186/0001-70 | D120: =F120 | E120: 11/2010 | F120: 2510.7319 | G120: 2860.07 | H120: =F120-G120 | I120: Mantido valor original da base (sem extrato) | J120: ESTIMADO (média c/ variação) | K120: =VALUE(RIGHT(A120,4)) | L120: =DATE(VALUE(RIGHT(A120,4)),VALUE(MID(A120,4,2)),1) | M120: =INDEX(IPCA!$D$5:$D$313,MATCH(Distrato!$B$3,IPCA!$A$5:$A$313,0))/INDEX(IPCA!$D$5:$D$313,MATCH(DATE(YEAR(L120),MONTH(L120)-1,1),IPCA!$A$5:$A$313,0)) | N120: =IF(L120>Distrato!$B$3,D120,D120*M120)
A121: 15/01/2011 | B121: TOTAL CENTRO DE DISTRIBUICAO INTEGRADA LTDA - 12.460.301/0001-87 | C121: FRUGIS REPRESENTACOES LTDA - 11.989.186/0001-70 | D121: =F121 | E121: 12/2010 | F121: 2458.339 | G121: 2970.45 | H121: =F121-G121 | I121: Mantido valor original da base (sem extrato) | J121: ESTIMADO (média c/ variação) | K121: =VALUE(RIGHT(A121,4)) | L121: =DATE(VALUE(RIGHT(A121,4)),VALUE(MID(A121,4,2)),1) | M121: =INDEX(IPCA!$D$5:$D$313,MATCH(Distrato!$B$3,IPCA!$A$5:$A$313,0))/INDEX(IPCA!$D$5:$D$313,MATCH(DATE(YEAR(L121),MONTH(L121)-1,1),IPCA!$A$5:$A$313,0)) | N121: =IF(L121>Distrato!$B$3,D121,D121*M121)
A122: 15/02/2011 | B122: TOTAL CENTRO DE DISTRIBUICAO INTEGRADA LTDA - 12.460.301/0001-87 | C122: FRUGIS REPRESENTACOES LTDA - 11.989.186/0001-70 | D122: =F122 | E122: 01/2011 | F122: 2652.658 | G122: 3393.14 | H122: =F122-G122 | I122: Mantido valor original da base (sem extrato) | J122: ESTIMADO (média c/ variação) | K122: =VALUE(RIGHT(A122,4)) | L122: =DATE(VALUE(RIGHT(A122,4)),VALUE(MID(A122,4,2)),1) | M122: =INDEX(IPCA!$D$5:$D$313,MATCH(Distrato!$B$3,IPCA!$A$5:$A$313,0))/INDEX(IPCA!$D$5:$D$313,MATCH(DATE(YEAR(L122),MONTH(L122)-1,1),IPCA!$A$5:$A$313,0)) | N122: =IF(L122>Distrato!$B$3,D122,D122*M122)
A123: 15/03/2011 | B123: TOTAL CENTRO DE DISTRIBUICAO INTEGRADA LTDA - 12.460.301/0001-87 | C123: FRUGIS REPRESENTACOES LTDA - 11.989.186/0001-70 | D123: =F123 | E123: 02/2011 | F123: 2658.3405 | G123: 2787.47 | H123: =F123-G123 | I123: Mantido valor original da base (sem extrato) | J123: ESTIMADO (média c/ variação) | K123: =VALUE(RIGHT(A123,4)) | L123: =DATE(VALUE(RIGHT(A123,4)),VALUE(MID(A123,4,2)),1) | M123: =INDEX(IPCA!$D$5:$D$313,MATCH(Distrato!$B$3,IPCA!$A$5:$A$313,0))/INDEX(IPCA!$D$5:$D$313,MATCH(DATE(YEAR(L123),MONTH(L123)-1,1),IPCA!$A$5:$A$313,0)) | N123: =IF(L123>Distrato!$B$3,D123,D123*M123)
A124: 15/04/2011 | B124: TOTAL CENTRO DE DISTRIBUICAO INTEGRADA LTDA - 12.460.301/0001-87 | C124: FRUGIS REPRESENTACOES LTDA - 11.989.186/0001-70 | D124: =F124 | E124: 03/2011 | F124: 2564.5952 | G124: 2995.85 | H124: =F124-G124 | I124: Mantido valor original da base (sem extrato) | J124: ESTIMADO (média c/ variação) | K124: =VALUE(RIGHT(A124,4)) | L124: =DATE(VALUE(RIGHT(A124,4)),VALUE(MID(A124,4,2)),1) | M124: =INDEX(IPCA!$D$5:$D$313,MATCH(Distrato!$B$3,IPCA!$A$5:$A$313,0))/INDEX(IPCA!$D$5:$D$313,MATCH(DATE(YEAR(L124),MONTH(L124)-1,1),IPCA!$A$5:$A$313,0)) | N124: =IF(L124>Distrato!$B$3,D124,D124*M124)
A125: 15/05/2011 | B125: TOTAL CENTRO DE DISTRIBUICAO INTEGRADA LTDA - 12.460.301/0001-87 | C125: FRUGIS REPRESENTACOES LTDA - 11.989.186/0001-70 | D125: =F125 | E125: 04/2011 | F125: 2602.8369 | G125: 3471.41 | H125: =F125-G125 | I125: Mantido valor original da base (sem extrato) | J125: ESTIMADO (média c/ variação) | K125: =VALUE(RIGHT(A125,4)) | L125: =DATE(VALUE(RIGHT(A125,4)),VALUE(MID(A125,4,2)),1) | M125: =INDEX(IPCA!$D$5:$D$313,MATCH(Distrato!$B$3,IPCA!$A$5:$A$313,0))/INDEX(IPCA!$D$5:$D$313,MATCH(DATE(YEAR(L125),MONTH(L125)-1,1),IPCA!$A$5:$A$313,0)) | N125: =IF(L125>Distrato!$B$3,D125,D125*M125)
A126: 15/06/2011 | B126: TOTAL CENTRO DE DISTRIBUICAO INTEGRADA LTDA - 12.460.301/0001-87 | C126: FRUGIS REPRESENTACOES LTDA - 11.989.186/0001-70 | D126: =F126 | E126: 05/2011 | F126: 2570.2187 | G126: 3530.64 | H126: =F126-G126 | I126: Mantido valor original da base (sem extrato) | J126: ESTIMADO (média c/ variação) | K126: =VALUE(RIGHT(A126,4)) | L126: =DATE(VALUE(RIGHT(A126,4)),VALUE(MID(A126,4,2)),1) | M126: =INDEX(IPCA!$D$5:$D$313,MATCH(Distrato!$B$3,IPCA!$A$5:$A$313,0))/INDEX(IPCA!$D$5:$D$313,MATCH(DATE(YEAR(L126),MONTH(L126)-1,1),IPCA!$A$5:$A$313,0)) | N126: =IF(L126>Distrato!$B$3,D126,D126*M126)
A127: 15/07/2011 | B127: TOTAL CENTRO DE DISTRIBUICAO INTEGRADA LTDA - 12.460.301/0001-87 | C127: FRUGIS REPRESENTACOES LTDA - 11.989.186/0001-70 | D127: =F127 | E127: 06/2011 | F127: 2670.6878 | G127: 3877.72 | H127: =F127-G127 | I127: Mantido valor original da base (sem extrato) | J127: ESTIMADO (média c/ variação) | K127: =VALUE(RIGHT(A127,4)) | L127: =DATE(VALUE(RIGHT(A127,4)),VALUE(MID(A127,4,2)),1) | M127: =INDEX(IPCA!$D$5:$D$313,MATCH(Distrato!$B$3,IPCA!$A$5:$A$313,0))/INDEX(IPCA!$D$5:$D$313,MATCH(DATE(YEAR(L127),MONTH(L127)-1,1),IPCA!$A$5:$A$313,0)) | N127: =IF(L127>Distrato!$B$3,D127,D127*M127)
A128: 15/08/2011 | B128: TOTAL CENTRO DE DISTRIBUICAO INTEGRADA LTDA - 12.460.301/0001-87 | C128: FRUGIS REPRESENTACOES LTDA - 11.989.186/0001-70 | D128: =F128 | E128: 07/2011 | F128: 2638.4449 | G128: 3728.81 | H128: =F128-G128 | I128: Mantido valor original da base (sem extrato) | J128: ESTIMADO (média c/ variação) | K128: =VALUE(RIGHT(A128,4)) | L128: =DATE(VALUE(RIGHT(A128,4)),VALUE(MID(A128,4,2)),1) | M128: =INDEX(IPCA!$D$5:$D$313,MATCH(Distrato!$B$3,IPCA!$A$5:$A$313,0))/INDEX(IPCA!$D$5:$D$313,MATCH(DATE(YEAR(L128),MONTH(L128)-1,1),IPCA!$A$5:$A$313,0)) | N128: =IF(L128>Distrato!$B$3,D128,D128*M128)
A129: 15/09/2011 | B129: TOTAL CENTRO DE DISTRIBUICAO INTEGRADA LTDA - 12.460.301/0001-87 | C129: FRUGIS REPRESENTACOES LTDA - 11.989.186/0001-70 | D129: =F129 | E129: 08/2011 | F129: 2599.1303 | G129: 4040.02 | H129: =F129-G129 | I129: Mantido valor original da base (sem extrato) | J129: ESTIMADO (média c/ variação) | K129: =VALUE(RIGHT(A129,4)) | L129: =DATE(VALUE(RIGHT(A129,4)),VALUE(MID(A129,4,2)),1) | M129: =INDEX(IPCA!$D$5:$D$313,MATCH(Distrato!$B$3,IPCA!$A$5:$A$313,0))/INDEX(IPCA!$D$5:$D$313,MATCH(DATE(YEAR(L129),MONTH(L129)-1,1),IPCA!$A$5:$A$313,0)) | N129: =IF(L129>Distrato!$B$3,D129,D129*M129)
A130: 15/10/2011 | B130: TOTAL CENTRO DE DISTRIBUICAO INTEGRADA LTDA - 12.460.301/0001-87 | C130: FRUGIS REPRESENTACOES LTDA - 11.989.186/0001-70 | D130: =F130 | E130: 09/2011 | F130: 2563.1852 | G130: 4192.88 | H130: =F130-G130 | I130: Mantido valor original da base (sem extrato) | J130: ESTIMADO (média c/ variação) | K130: =VALUE(RIGHT(A130,4)) | L130: =DATE(VALUE(RIGHT(A130,4)),VALUE(MID(A130,4,2)),1) | M130: =INDEX(IPCA!$D$5:$D$313,MATCH(Distrato!$B$3,IPCA!$A$5:$A$313,0))/INDEX(IPCA!$D$5:$D$313,MATCH(DATE(YEAR(L130),MONTH(L130)-1,1),IPCA!$A$5:$A$313,0)) | N130: =IF(L130>Distrato!$B$3,D130,D130*M130)
... A133: 15/01/2012 | B133: TOTAL CENTRO DE DISTRIBUICAO INTEGRADA LTDA - 12.460.301/0001-87 | C133: FRUGIS REPRESENTACOES LTDA - 11.989.186/0001-70 | D133: =F133 | E133: 12/2011 | F133: 2652.7385 | G133: 3861.13 | H133: =F133-G133 | I133: Mantido valor original da base (sem extrato) | J133: ESTIMADO (média c/ variação) | K133: =VALUE(RIGHT(A133,4)) | L133: =DATE(VALUE(RIGHT(A133,4)),VALUE(MID(A133,4,2)),1) | M133: =INDEX(IPCA!$D$5:$D$313,MATCH(Distrato!$B$3,IPCA!$A$5:$A$313,0))/INDEX(IPCA!$D$5:$D$313,MATCH(DATE(YEAR(L133),MONTH(L133)-1,1),IPCA!$A$5:$A$313,0)) | N133: =IF(L133>Distrato!$B$3,D133,D133*M133)
...

Sheet Distrato
A1: Distrato - comissões atualizadas pelo IPCA, uma a uma (Lei 4.886/65)
A3: Mês de referência da correção | B3: 46235 | C3: Último IPCA divulgado (ago/2026). Cada comissão é corrigida do mês do pagamento até este mês (inclusive).
A4: Início do Cenário B (pagamento) | B4: 44409 | C4: Premissa: distrato de 2021 teria quitado o período anterior.
A6: CENÁRIO A - todo o período (fev/2001 a ago/2026)
A7: Soma das comissões (nominal) | B7: =SUMIFS('Resumo Pagamento'!$D$2:$D$308,'Resumo Pagamento'!$L$2:$L$308,"<="&$B$3)
A8: Soma das comissões corrigidas pelo IPCA | B8: =SUMIFS('Resumo Pagamento'!$N$2:$N$308,'Resumo Pagamento'!$L$2:$L$308,"<="&$B$3)
A9: Correção monetária no período | B9: =B8-B7
A10: Indenização: 1/12 do total corrigido (art. 27, "j") | B10: =B8/12
A11: Aviso prévio: 1/3 das comissões corrigidas dos últimos 3 meses (art. 34) | B11: =SUMIFS('Resumo Pagamento'!$N$2:$N$308,'Resumo Pagamento'!$L$2:$L$308,">="&DATE(YEAR($B$3),MONTH($B$3)-2,1),'Resumo Pagamento'!$L$2:$L$308,"<="&$B$3)/3
A12: TOTAL DISTRATO - CENÁRIO A | B12: =B10+B11
A14: CENÁRIO B - a partir do início informado em B4
A15: Soma das comissões (nominal) | B15: =SUMIFS('Resumo Pagamento'!$D$2:$D$308,'Resumo Pagamento'!$L$2:$L$308,">="&$B$4,'Resumo Pagamento'!$L$2:$L$308,"<="&$B$3)
A16: Soma das comissões corrigidas pelo IPCA | B16: =SUMIFS('Resumo Pagamento'!$N$2:$N$308,'Resumo Pagamento'!$L$2:$L$308,">="&$B$4,'Resumo Pagamento'!$L$2:$L$308,"<="&$B$3)
A17: Indenização: 1/12 do total corrigido | B17: =B16/12
A18: Aviso prévio (mesmo do Cenário A) | B18: =B11
A19: TOTAL DISTRATO - CENÁRIO B | B19: =B17+B18
A21: Base: coluna D da aba Resumo Pagamento (valor FINAL: extrato real, 2007 estimado, base manual e complementado). Correção: fator = índice IPCA do mês de referência ÷ índice do mês anterior ao pagamento (mesma lógica da Calculadora do Cidadão do BCB).
A22: IPCA de 2001 a 2025 está distribuído igualmente nos meses a partir do IPCA anual oficial; 2026 é mensal oficial. Para precisão total, cole a série mensal oficial na aba IPCA (coluna B).
A25: Por ano de pagamento
A26: Ano | B26: Nominal (R$) | C26: Corrigido IPCA (R$)
A27: 2001 | B27: =SUMIFS('Resumo Pagamento'!$D$2:$D$308,'Resumo Pagamento'!$K$2:$K$308,A27) | C27: =SUMIFS('Resumo Pagamento'!$N$2:$N$308,'Resumo Pagamento'!$K$2:$K$308,A27)
A28: 2002 | B28: =SUMIFS('Resumo Pagamento'!$D$2:$D$308,'Resumo Pagamento'!$K$2:$K$308,A28) | C28: =SUMIFS('Resumo Pagamento'!$N$2:$N$308,'Resumo Pagamento'!$K$2:$K$308,A28)
A29: 2003 | B29: =SUMIFS('Resumo Pagamento'!$D$2:$D$308,'Resumo Pagamento'!$K$2:$K$308,A29) | C29: =SUMIFS('Resumo Pagamento'!$N$2:$N$308,'Resumo Pagamento'!$K$2:$K$308,A29)
A30: 2004 | B30: =SUMIFS('Resumo Pagamento'!$D$2:$D$308,'Resumo Pagamento'!$K$2:$K$308,A30) | C30: =SUMIFS('Resumo Pagamento'!$N$2:$N$308,'Resumo Pagamento'!$K$2:$K$308,A30)
A31: 2005 | B31: =SUMIFS('Resumo Pagamento'!$D$2:$D$308,'Resumo Pagamento'!$K$2:$K$308,A31) | C31: =SUMIFS('Resumo Pagamento'!$N$2:$N$308,'Resumo Pagamento'!$K$2:$K$308,A31)
A32: 2006 | B32: =SUMIFS('Resumo Pagamento'!$D$2:$D$308,'Resumo Pagamento'!$K$2:$K$308,A32) | C32: =SUMIFS('Resumo Pagamento'!$N$2:$N$308,'Resumo Pagamento'!$K$2:$K$308,A32)
A33: 2007 | B33: =SUMIFS('Resumo Pagamento'!$D$2:$D$308,'Resumo Pagamento'!$K$2:$K$308,A33) | C33: =SUMIFS('Resumo Pagamento'!$N$2:$N$308,'Resumo Pagamento'!$K$2:$K$308,A33)
A34: 2008 | B34: =SUMIFS('Resumo Pagamento'!$D$2:$D$308,'Resumo Pagamento'!$K$2:$K$308,A34) | C34: =SUMIFS('Resumo Pagamento'!$N$2:$N$308,'Resumo Pagamento'!$K$2:$K$308,A34)
A35: 2009 | B35: =SUMIFS('Resumo Pagamento'!$D$2:$D$308,'Resumo Pagamento'!$K$2:$K$308,A35) | C35: =SUMIFS('Resumo Pagamento'!$N$2:$N$308,'Resumo Pagamento'!$K$2:$K$308,A35)
A36: 2010 | B36: =SUMIFS('Resumo Pagamento'!$D$2:$D$308,'Resumo Pagamento'!$K$2:$K$308,A36) | C36: =SUMIFS('Resumo Pagamento'!$N$2:$N$308,'Resumo Pagamento'!$K$2:$K$308,A36)
A37: 2011 | B37: =SUMIFS('Resumo Pagamento'!$D$2:$D$308,'Resumo Pagamento'!$K$2:$K$308,A37) | C37: =SUMIFS('Resumo Pagamento'!$N$2:$N$308,'Resumo Pagamento'!$K$2:$K$308,A37)
A38: 2012 | B38: =SUMIFS('Resumo Pagamento'!$D$2:$D$308,'Resumo Pagamento'!$K$2:$K$308,A38) | C38: =SUMIFS('Resumo Pagamento'!$N$2:$N$308,'Resumo Pagamento'!$K$2:$K$308,A38)
... A52: 2026 | B52: =SUMIFS('Resumo Pagamento'!$D$2:$D$308,'Resumo Pagamento'!$K$2:$K$308,A52) | C52: =SUMIFS('Resumo Pagamento'!$N$2:$N$308,'Resumo Pagamento'!$K$2:$K$308,A52)
A53: TOTAL | B53: =SUM(B27:B52) | C53: =SUM(C27:C52)

Sheet Origem dos Valores
A1: Ano do pagamento | B1: Extrato real (Tenda) | C1: 2007 estimado (2008 ÷ IPCA) | D1: Mantido da base manual | E1: Complementado - real | F1: Complementado - ESTIMADO | G1: Total | H1: % estimado ou manual
A2: 2001 | B2: =SUMIFS('Resumo Pagamento'!$D$2:$D$308,'Resumo Pagamento'!$K$2:$K$308,A2,'Resumo Pagamento'!$I$2:$I$308,"*xtrato real*") | C2: =SUMIFS('Resumo Pagamento'!$D$2:$D$308,'Resumo Pagamento'!$K$2:$K$308,A2,'Resumo Pagamento'!$I$2:$I$308,"2007*") | D2: =SUMIFS('Resumo Pagamento'!$D$2:$D$308,'Resumo Pagamento'!$K$2:$K$308,A2,'Resumo Pagamento'!$I$2:$I$308,"Mantido*") | E2: =SUMIFS('Resumo Pagamento'!$D$2:$D$308,'Resumo Pagamento'!$K$2:$K$308,A2,'Resumo Pagamento'!$I$2:$I$308,"Complementado (não existia na base)") | F2: =SUMIFS('Resumo Pagamento'!$D$2:$D$308,'Resumo Pagamento'!$K$2:$K$308,A2,'Resumo Pagamento'!$I$2:$I$308,"*ESTIMADO") | G2: =SUM(B2:F2) | H2: =IF(G2=0,"",(C2+D2+F2)/G2)
A3: 2002 | B3: =SUMIFS('Resumo Pagamento'!$D$2:$D$308,'Resumo Pagamento'!$K$2:$K$308,A3,'Resumo Pagamento'!$I$2:$I$308,"*xtrato real*") | C3: =SUMIFS('Resumo Pagamento'!$D$2:$D$308,'Resumo Pagamento'!$K$2:$K$308,A3,'Resumo Pagamento'!$I$2:$I$308,"2007*") | D3: =SUMIFS('Resumo Pagamento'!$D$2:$D$308,'Resumo Pagamento'!$K$2:$K$308,A3,'Resumo Pagamento'!$I$2:$I$308,"Mantido*") | E3: =SUMIFS('Resumo Pagamento'!$D$2:$D$308,'Resumo Pagamento'!$K$2:$K$308,A3,'Resumo Pagamento'!$I$2:$I$308,"Complementado (não existia na base)") | F3: =SUMIFS('Resumo Pagamento'!$D$2:$D$308,'Resumo Pagamento'!$K$2:$K$308,A3,'Resumo Pagamento'!$I$2:$I$308,"*ESTIMADO") | G3: =SUM(B3:F3) | H3: =IF(G3=0,"",(C3+D3+F3)/G3)
A4: 2003 | B4: =SUMIFS('Resumo Pagamento'!$D$2:$D$308,'Resumo Pagamento'!$K$2:$K$308,A4,'Resumo Pagamento'!$I$2:$I$308,"*xtrato real*") | C4: =SUMIFS('Resumo Pagamento'!$D$2:$D$308,'Resumo Pagamento'!$K$2:$K$308,A4,'Resumo Pagamento'!$I$2:$I$308,"2007*") | D4: =SUMIFS('Resumo Pagamento'!$D$2:$D$308,'Resumo Pagamento'!$K$2:$K$308,A4,'Resumo Pagamento'!$I$2:$I$308,"Mantido*") | E4: =SUMIFS('Resumo Pagamento'!$D$2:$D$308,'Resumo Pagamento'!$K$2:$K$308,A4,'Resumo Pagamento'!$I$2:$I$308,"Complementado (não existia na base)") | F4: =SUMIFS('Resumo Pagamento'!$D$2:$D$308,'Resumo Pagamento'!$K$2:$K$308,A4,'Resumo Pagamento'!$I$2:$I$308,"*ESTIMADO") | G4: =SUM(B4:F4) | H4: =IF(G4=0,"",(C4+D4+F4)/G4)
A5: 2004 | B5: =SUMIFS('Resumo Pagamento'!$D$2:$D$308,'Resumo Pagamento'!$K$2:$K$308,A5,'Resumo Pagamento'!$I$2:$I$308,"*xtrato real*") | C5: =SUMIFS('Resumo Pagamento'!$D$2:$D$308,'Resumo Pagamento'!$K$2:$K$308,A5,'Resumo Pagamento'!$I$2:$I$308,"2007*") | D5: =SUMIFS('Resumo Pagamento'!$D$2:$D$308,'Resumo Pagamento'!$K$2:$K$308,A5,'Resumo Pagamento'!$I$2:$I$308,"Mantido*") | E5: =SUMIFS('Resumo Pagamento'!$D$2:$D$308,'Resumo Pagamento'!$K$2:$K$308,A5,'Resumo Pagamento'!$I$2:$I$308,"Complementado (não existia na base)") | F5: =SUMIFS('Resumo Pagamento'!$D$2:$D$308,'Resumo Pagamento'!$K$2:$K$308,A5,'Resumo Pagamento'!$I$2:$I$308,"*ESTIMADO") | G5: =SUM(B5:F5) | H5: =IF(G5=0,"",(C5+D5+F5)/G5)
A6: 2005 | B6: =SUMIFS('Resumo Pagamento'!$D$2:$D$308,'Resumo Pagamento'!$K$2:$K$308,A6,'Resumo Pagamento'!$I$2:$I$308,"*xtrato real*") | C6: =SUMIFS('Resumo Pagamento'!$D$2:$D$308,'Resumo Pagamento'!$K$2:$K$308,A6,'Resumo Pagamento'!$I$2:$I$308,"2007*") | D6: =SUMIFS('Resumo Pagamento'!$D$2:$D$308,'Resumo Pagamento'!$K$2:$K$308,A6,'Resumo Pagamento'!$I$2:$I$308,"Mantido*") | E6: =SUMIFS('Resumo Pagamento'!$D$2:$D$308,'Resumo Pagamento'!$K$2:$K$308,A6,'Resumo Pagamento'!$I$2:$I$308,"Complementado (não existia na base)") | F6: =SUMIFS('Resumo Pagamento'!$D$2:$D$308,'Resumo Pagamento'!$K$2:$K$308,A6,'Resumo Pagamento'!$I$2:$I$308,"*ESTIMADO") | G6: =SUM(B6:F6) | H6: =IF(G6=0,"",(C6+D6+F6)/G6)
A7: 2006 | B7: =SUMIFS('Resumo Pagamento'!$D$2:$D$308,'Resumo Pagamento'!$K$2:$K$308,A7,'Resumo Pagamento'!$I$2:$I$308,"*xtrato real*") | C7: =SUMIFS('Resumo Pagamento'!$D$2:$D$308,'Resumo Pagamento'!$K$2:$K$308,A7,'Resumo Pagamento'!$I$2:$I$308,"2007*") | D7: =SUMIFS('Resumo Pagamento'!$D$2:$D$308,'Resumo Pagamento'!$K$2:$K$308,A7,'Resumo Pagamento'!$I$2:$I$308,"Mantido*") | E7: =SUMIFS('Resumo Pagamento'!$D$2:$D$308,'Resumo Pagamento'!$K$2:$K$308,A7,'Resumo Pagamento'!$I$2:$I$308,"Complementado (não existia na base)") | F7: =SUMIFS('Resumo Pagamento'!$D$2:$D$308,'Resumo Pagamento'!$K$2:$K$308,A7,'Resumo Pagamento'!$I$2:$I$308,"*ESTIMADO") | G7: =SUM(B7:F7) | H7: =IF(G7=0,"",(C7+D7+F7)/G7)
A8: 2007 | B8: =SUMIFS('Resumo Pagamento'!$D$2:$D$308,'Resumo Pagamento'!$K$2:$K$308,A8,'Resumo Pagamento'!$I$2:$I$308,"*xtrato real*") | C8: =SUMIFS('Resumo Pagamento'!$D$2:$D$308,'Resumo Pagamento'!$K$2:$K$308,A8,'Resumo Pagamento'!$I$2:$I$308,"2007*") | D8: =SUMIFS('Resumo Pagamento'!$D$2:$D$308,'Resumo Pagamento'!$K$2:$K$308,A8,'Resumo Pagamento'!$I$2:$I$308,"Mantido*") | E8: =SUMIFS('Resumo Pagamento'!$D$2:$D$308,'Resumo Pagamento'!$K$2:$K$308,A8,'Resumo Pagamento'!$I$2:$I$308,"Complementado (não existia na base)") | F8: =SUMIFS('Resumo Pagamento'!$D$2:$D$308,'Resumo Pagamento'!$K$2:$K$308,A8,'Resumo Pagamento'!$I$2:$I$308,"*ESTIMADO") | G8: =SUM(B8:F8) | H8: =IF(G8=0,"",(C8+D8+F8)/G8)
A9: 2008 | B9: =SUMIFS('Resumo Pagamento'!$D$2:$D$308,'Resumo Pagamento'!$K$2:$K$308,A9,'Resumo Pagamento'!$I$2:$I$308,"*xtrato real*") | C9: =SUMIFS('Resumo Pagamento'!$D$2:$D$308,'Resumo Pagamento'!$K$2:$K$308,A9,'Resumo Pagamento'!$I$2:$I$308,"2007*") | D9: =SUMIFS('Resumo Pagamento'!$D$2:$D$308,'Resumo Pagamento'!$K$2:$K$308,A9,'Resumo Pagamento'!$I$2:$I$308,"Mantido*") | E9: =SUMIFS('Resumo Pagamento'!$D$2:$D$308,'Resumo Pagamento'!$K$2:$K$308,A9,'Resumo Pagamento'!$I$2:$I$308,"Complementado (não existia na base)") | F9: =SUMIFS('Resumo Pagamento'!$D$2:$D$308,'Resumo Pagamento'!$K$2:$K$308,A9,'Resumo Pagamento'!$I$2:$I$308,"*ESTIMADO") | G9: =SUM(B9:F9) | H9: =IF(G9=0,"",(C9+D9+F9)/G9)
A10: 2009 | B10: =SUMIFS('Resumo Pagamento'!$D$2:$D$308,'Resumo Pagamento'!$K$2:$K$308,A10,'Resumo Pagamento'!$I$2:$I$308,"*xtrato real*") | C10: =SUMIFS('Resumo Pagamento'!$D$2:$D$308,'Resumo Pagamento'!$K$2:$K$308,A10,'Resumo Pagamento'!$I$2:$I$308,"2007*") | D10: =SUMIFS('Resumo Pagamento'!$D$2:$D$308,'Resumo Pagamento'!$K$2:$K$308,A10,'Resumo Pagamento'!$I$2:$I$308,"Mantido*") | E10: =SUMIFS('Resumo Pagamento'!$D$2:$D$308,'Resumo Pagamento'!$K$2:$K$308,A10,'Resumo Pagamento'!$I$2:$I$308,"Complementado (não existia na base)") | F10: =SUMIFS('Resumo Pagamento'!$D$2:$D$308,'Resumo Pagamento'!$K$2:$K$308,A10,'Resumo Pagamento'!$I$2:$I$308,"*ESTIMADO") | G10: =SUM(B10:F10) | H10: =IF(G10=0,"",(C10+D10+F10)/G10)
A11: 2010 | B11: =SUMIFS('Resumo Pagamento'!$D$2:$D$308,'Resumo Pagamento'!$K$2:$K$308,A11,'Resumo Pagamento'!$I$2:$I$308,"*xtrato real*") | C11: =SUMIFS('Resumo Pagamento'!$D$2:$D$308,'Resumo Pagamento'!$K$2:$K$308,A11,'Resumo Pagamento'!$I$2:$I$308,"2007*") | D11: =SUMIFS('Resumo Pagamento'!$D$2:$D$308,'Resumo Pagamento'!$K$2:$K$308,A11,'Resumo Pagamento'!$I$2:$I$308,"Mantido*") | E11: =SUMIFS('Resumo Pagamento'!$D$2:$D$308,'Resumo Pagamento'!$K$2:$K$308,A11,'Resumo Pagamento'!$I$2:$I$308,"Complementado (não existia na base)") | F11: =SUMIFS('Resumo Pagamento'!$D$2:$D$308,'Resumo Pagamento'!$K$2:$K$308,A11,'Resumo Pagamento'!$I$2:$I$308,"*ESTIMADO") | G11: =SUM(B11:F11) | H11: =IF(G11=0,"",(C11+D11+F11)/G11)
A12: 2011 | B12: =SUMIFS('Resumo Pagamento'!$D$2:$D$308,'Resumo Pagamento'!$K$2:$K$308,A12,'Resumo Pagamento'!$I$2:$I$308,"*xtrato real*") | C12: =SUMIFS('Resumo Pagamento'!$D$2:$D$308,'Resumo Pagamento'!$K$2:$K$308,A12,'Resumo Pagamento'!$I$2:$I$308,"2007*") | D12: =SUMIFS('Resumo Pagamento'!$D$2:$D$308,'Resumo Pagamento'!$K$2:$K$308,A12,'Resumo Pagamento'!$I$2:$I$308,"Mantido*") | E12: =SUMIFS('Resumo Pagamento'!$D$2:$D$308,'Resumo Pagamento'!$K$2:$K$308,A12,'Resumo Pagamento'!$I$2:$I$308,"Complementado (não existia na base)") | F12: =SUMIFS('Resumo Pagamento'!$D$2:$D$308,'Resumo Pagamento'!$K$2:$K$308,A12,'Resumo Pagamento'!$I$2:$I$308,"*ESTIMADO") | G12: =SUM(B12:F12) | H12: =IF(G12=0,"",(C12+D12+F12)/G12)
A13: 2012 | B13: =SUMIFS('Resumo Pagamento'!$D$2:$D$308,'Resumo Pagamento'!$K$2:$K$308,A13,'Resumo Pagamento'!$I$2:$I$308,"*xtrato real*") | C13: =SUMIFS('Resumo Pagamento'!$D$2:$D$308,'Resumo Pagamento'!$K$2:$K$308,A13,'Resumo Pagamento'!$I$2:$I$308,"2007*") | D13: =SUMIFS('Resumo Pagamento'!$D$2:$D$308,'Resumo Pagamento'!$K$2:$K$308,A13,'Resumo Pagamento'!$I$2:$I$308,"Mantido*") | E13: =SUMIFS('Resumo Pagamento'!$D$2:$D$308,'Resumo Pagamento'!$K$2:$K$308,A13,'Resumo Pagamento'!$I$2:$I$308,"Complementado (não existia na base)") | F13: =SUMIFS('Resumo Pagamento'!$D$2:$D$308,'Resumo Pagamento'!$K$2:$K$308,A13,'Resumo Pagamento'!$I$2:$I$308,"*ESTIMADO") | G13: =SUM(B13:F13) | H13: =IF(G13=0,"",(C13+D13+F13)/G13)
... A27: 2026 | B27: =SUMIFS('Resumo Pagamento'!$D$2:$D$308,'Resumo Pagamento'!$K$2:$K$308,A27,'Resumo Pagamento'!$I$2:$I$308,"*xtrato real*") | C27: =SUMIFS('Resumo Pagamento'!$D$2:$D$308,'Resumo Pagamento'!$K$2:$K$308,A27,'Resumo Pagamento'!$I$2:$I$308,"2007*") | D27: =SUMIFS('Resumo Pagamento'!$D$2:$D$308,'Resumo Pagamento'!$K$2:$K$308,A27,'Resumo Pagamento'!$I$2:$I$308,"Mantido*") | E27: =SUMIFS('Resumo Pagamento'!$D$2:$D$308,'Resumo Pagamento'!$K$2:$K$308,A27,'Resumo Pagamento'!$I$2:$I$308,"Complementado (não existia na base)") | F27: =SUMIFS('Resumo Pagamento'!$D$2:$D$308,'Resumo Pagamento'!$K$2:$K$308,A27,'Resumo Pagamento'!$I$2:$I$308,"*ESTIMADO") | G27: =SUM(B27:F27) | H27: =IF(G27=0,"",(C27+D27+F27)/G27)
A28: TOTAL | B28: =SUM(B2:B27) | C28: =SUM(C2:C27) | D28: =SUM(D2:D27) | E28: =SUM(E2:E27) | F28: =SUM(F2:F27) | G28: =SUM(G2:G27) | H28: =IF(G28=0,"",(C28+D28+F28)/G28)
A30: Complementado - real: extrato Tenda (fev/2012 a fev/2013) e contas a pagar (jul/2017 em diante). Complementado - ESTIMADO: mar/2013 a jun/2017 (média com variação). Mantido da base manual: 2001 a jan/2005 e nov/2010 a jan/2012 (valores da planilha original, aparentemente estimados).

Sheet Comparação Anual
A1: Ano do pagamento | B1: Base original (R$) | C1: Final - coluna D (R$) | D1: Diferença (Final − Original) | E1: Meses com extrato real | F1: Meses mantidos da base | G1: Meses complementados
A2: 2001 | B2: =SUMIFS('Resumo Pagamento'!$F$2:$F$308,'Resumo Pagamento'!$K$2:$K$308,A2) | C2: =SUMIFS('Resumo Pagamento'!$D$2:$D$308,'Resumo Pagamento'!$K$2:$K$308,A2) | D2: =C2-B2 | E2: =COUNTIFS('Resumo Pagamento'!$K$2:$K$308,A2,'Resumo Pagamento'!$I$2:$I$308,"*xtrato real*") | F2: =COUNTIFS('Resumo Pagamento'!$K$2:$K$308,A2,'Resumo Pagamento'!$I$2:$I$308,"Mantido*") | G2: =COUNTIFS('Resumo Pagamento'!$K$2:$K$308,A2,'Resumo Pagamento'!$I$2:$I$308,"Complementado*")
A3: 2002 | B3: =SUMIFS('Resumo Pagamento'!$F$2:$F$308,'Resumo Pagamento'!$K$2:$K$308,A3) | C3: =SUMIFS('Resumo Pagamento'!$D$2:$D$308,'Resumo Pagamento'!$K$2:$K$308,A3) | D3: =C3-B3 | E3: =COUNTIFS('Resumo Pagamento'!$K$2:$K$308,A3,'Resumo Pagamento'!$I$2:$I$308,"*xtrato real*") | F3: =COUNTIFS('Resumo Pagamento'!$K$2:$K$308,A3,'Resumo Pagamento'!$I$2:$I$308,"Mantido*") | G3: =COUNTIFS('Resumo Pagamento'!$K$2:$K$308,A3,'Resumo Pagamento'!$I$2:$I$308,"Complementado*")
A4: 2003 | B4: =SUMIFS('Resumo Pagamento'!$F$2:$F$308,'Resumo Pagamento'!$K$2:$K$308,A4) | C4: =SUMIFS('Resumo Pagamento'!$D$2:$D$308,'Resumo Pagamento'!$K$2:$K$308,A4) | D4: =C4-B4 | E4: =COUNTIFS('Resumo Pagamento'!$K$2:$K$308,A4,'Resumo Pagamento'!$I$2:$I$308,"*xtrato real*") | F4: =COUNTIFS('Resumo Pagamento'!$K$2:$K$308,A4,'Resumo Pagamento'!$I$2:$I$308,"Mantido*") | G4: =COUNTIFS('Resumo Pagamento'!$K$2:$K$308,A4,'Resumo Pagamento'!$I$2:$I$308,"Complementado*")
A5: 2004 | B5: =SUMIFS('Resumo Pagamento'!$F$2:$F$308,'Resumo Pagamento'!$K$2:$K$308,A5) | C5: =SUMIFS('Resumo Pagamento'!$D$2:$D$308,'Resumo Pagamento'!$K$2:$K$308,A5) | D5: =C5-B5 | E5: =COUNTIFS('Resumo Pagamento'!$K$2:$K$308,A5,'Resumo Pagamento'!$I$2:$I$308,"*xtrato real*") | F5: =COUNTIFS('Resumo Pagamento'!$K$2:$K$308,A5,'Resumo Pagamento'!$I$2:$I$308,"Mantido*") | G5: =COUNTIFS('Resumo Pagamento'!$K$2:$K$308,A5,'Resumo Pagamento'!$I$2:$I$308,"Complementado*")
A6: 2005 | B6: =SUMIFS('Resumo Pagamento'!$F$2:$F$308,'Resumo Pagamento'!$K$2:$K$308,A6) | C6: =SUMIFS('Resumo Pagamento'!$D$2:$D$308,'Resumo Pagamento'!$K$2:$K$308,A6) | D6: =C6-B6 | E6: =COUNTIFS('Resumo Pagamento'!$K$2:$K$308,A6,'Resumo Pagamento'!$I$2:$I$308,"*xtrato real*") | F6: =COUNTIFS('Resumo Pagamento'!$K$2:$K$308,A6,'Resumo Pagamento'!$I$2:$I$308,"Mantido*") | G6: =COUNTIFS('Resumo Pagamento'!$K$2:$K$308,A6,'Resumo Pagamento'!$I$2:$I$308,"Complementado*")
A7: 2006 | B7: =SUMIFS('Resumo Pagamento'!$F$2:$F$308,'Resumo Pagamento'!$K$2:$K$308,A7) | C7: =SUMIFS('Resumo Pagamento'!$D$2:$D$308,'Resumo Pagamento'!$K$2:$K$308,A7) | D7: =C7-B7 | E7: =COUNTIFS('Resumo Pagamento'!$K$2:$K$308,A7,'Resumo Pagamento'!$I$2:$I$308,"*xtrato real*") | F7: =COUNTIFS('Resumo Pagamento'!$K$2:$K$308,A7,'Resumo Pagamento'!$I$2:$I$308,"Mantido*") | G7: =COUNTIFS('Resumo Pagamento'!$K$2:$K$308,A7,'Resumo Pagamento'!$I$2:$I$308,"Complementado*")
A8: 2007 | B8: =SUMIFS('Resumo Pagamento'!$F$2:$F$308,'Resumo Pagamento'!$K$2:$K$308,A8) | C8: =SUMIFS('Resumo Pagamento'!$D$2:$D$308,'Resumo Pagamento'!$K$2:$K$308,A8) | D8: =C8-B8 | E8: =COUNTIFS('Resumo Pagamento'!$K$2:$K$308,A8,'Resumo Pagamento'!$I$2:$I$308,"*xtrato real*") | F8: =COUNTIFS('Resumo Pagamento'!$K$2:$K$308,A8,'Resumo Pagamento'!$I$2:$I$308,"Mantido*") | G8: =COUNTIFS('Resumo Pagamento'!$K$2:$K$308,A8,'Resumo Pagamento'!$I$2:$I$308,"Complementado*")
A9: 2008 | B9: =SUMIFS('Resumo Pagamento'!$F$2:$F$308,'Resumo Pagamento'!$K$2:$K$308,A9) | C9: =SUMIFS('Resumo Pagamento'!$D$2:$D$308,'Resumo Pagamento'!$K$2:$K$308,A9) | D9: =C9-B9 | E9: =COUNTIFS('Resumo Pagamento'!$K$2:$K$308,A9,'Resumo Pagamento'!$I$2:$I$308,"*xtrato real*") | F9: =COUNTIFS('Resumo Pagamento'!$K$2:$K$308,A9,'Resumo Pagamento'!$I$2:$I$308,"Mantido*") | G9: =COUNTIFS('Resumo Pagamento'!$K$2:$K$308,A9,'Resumo Pagamento'!$I$2:$I$308,"Complementado*")
A10: 2009 | B10: =SUMIFS('Resumo Pagamento'!$F$2:$F$308,'Resumo Pagamento'!$K$2:$K$308,A10) | C10: =SUMIFS('Resumo Pagamento'!$D$2:$D$308,'Resumo Pagamento'!$K$2:$K$308,A10) | D10: =C10-B10 | E10: =COUNTIFS('Resumo Pagamento'!$K$2:$K$308,A10,'Resumo Pagamento'!$I$2:$I$308,"*xtrato real*") | F10: =COUNTIFS('Resumo Pagamento'!$K$2:$K$308,A10,'Resumo Pagamento'!$I$2:$I$308,"Mantido*") | G10: =COUNTIFS('Resumo Pagamento'!$K$2:$K$308,A10,'Resumo Pagamento'!$I$2:$I$308,"Complementado*")
A11: 2010 | B11: =SUMIFS('Resumo Pagamento'!$F$2:$F$308,'Resumo Pagamento'!$K$2:$K$308,A11) | C11: =SUMIFS('Resumo Pagamento'!$D$2:$D$308,'Resumo Pagamento'!$K$2:$K$308,A11) | D11: =C11-B11 | E11: =COUNTIFS('Resumo Pagamento'!$K$2:$K$308,A11,'Resumo Pagamento'!$I$2:$I$308,"*xtrato real*") | F11: =COUNTIFS('Resumo Pagamento'!$K$2:$K$308,A11,'Resumo Pagamento'!$I$2:$I$308,"Mantido*") | G11: =COUNTIFS('Resumo Pagamento'!$K$2:$K$308,A11,'Resumo Pagamento'!$I$2:$I$308,"Complementado*")
A12: 2011 | B12: =SUMIFS('Resumo Pagamento'!$F$2:$F$308,'Resumo Pagamento'!$K$2:$K$308,A12) | C12: =SUMIFS('Resumo Pagamento'!$D$2:$D$308,'Resumo Pagamento'!$K$2:$K$308,A12) | D12: =C12-B12 | E12: =COUNTIFS('Resumo Pagamento'!$K$2:$K$308,A12,'Resumo Pagamento'!$I$2:$I$308,"*xtrato real*") | F12: =COUNTIFS('Resumo Pagamento'!$K$2:$K$308,A12,'Resumo Pagamento'!$I$2:$I$308,"Mantido*") | G12: =COUNTIFS('Resumo Pagamento'!$K$2:$K$308,A12,'Resumo Pagamento'!$I$2:$I$308,"Complementado*")
A13: 2012 | B13: =SUMIFS('Resumo Pagamento'!$F$2:$F$308,'Resumo Pagamento'!$K$2:$K$308,A13) | C13: =SUMIFS('Resumo Pagamento'!$D$2:$D$308,'Resumo Pagamento'!$K$2:$K$308,A13) | D13: =C13-B13 | E13: =COUNTIFS('Resumo Pagamento'!$K$2:$K$308,A13,'Resumo Pagamento'!$I$2:$I$308,"*xtrato real*") | F13: =COUNTIFS('Resumo Pagamento'!$K$2:$K$308,A13,'Resumo Pagamento'!$I$2:$I$308,"Mantido*") | G13: =COUNTIFS('Resumo Pagamento'!$K$2:$K$308,A13,'Resumo Pagamento'!$I$2:$I$308,"Complementado*")
... A27: 2026 | B27: =SUMIFS('Resumo Pagamento'!$F$2:$F$308,'Resumo Pagamento'!$K$2:$K$308,A27) | C27: =SUMIFS('Resumo Pagamento'!$D$2:$D$308,'Resumo Pagamento'!$K$2:$K$308,A27) | D27: =C27-B27 | E27: =COUNTIFS('Resumo Pagamento'!$K$2:$K$308,A27,'Resumo Pagamento'!$I$2:$I$308,"*xtrato real*") | F27: =COUNTIFS('Resumo Pagamento'!$K$2:$K$308,A27,'Resumo Pagamento'!$I$2:$I$308,"Mantido*") | G27: =COUNTIFS('Resumo Pagamento'!$K$2:$K$308,A27,'Resumo Pagamento'!$I$2:$I$308,"Complementado*")
A28: TOTAL | B28: =SUM(B2:B27) | C28: =SUM(C2:C27) | D28: =SUM(D2:D27) | E28: =SUM(E2:E27) | F28: =SUM(F2:F27) | G28: =SUM(G2:G27)

Sheet IPCA
A1: IPCA - índice mensal usado na correção (fonte: IBGE)
A2: Coluna B (amarela) é editável: cole a série oficial mensal do IPCA (BCB-SGS 433 / IBGE SIDRA 1737) para substituir as aproximações. Tudo recalcula sozinho.
A4: Mês | B4: IPCA do mês (%) | C4: Fonte | D4: Índice acumulado (dez/2000 = 1)
A5: 36861 | C5: Base | D5: 1
A6: 36892 | B6: 0.61774 | C6: Aproximação: IPCA anual 7.67% (IBGE) distribuído igualmente nos 12 meses | D6: =D5*(1+B6/100)
A7: 36923 | B7: 0.61774 | C7: Aproximação: IPCA anual 7.67% (IBGE) distribuído igualmente nos 12 meses | D7: =D6*(1+B7/100)
A8: 36951 | B8: 0.61774 | C8: Aproximação: IPCA anual 7.67% (IBGE) distribuído igualmente nos 12 meses | D8: =D7*(1+B8/100)
A9: 36982 | B9: 0.61774 | C9: Aproximação: IPCA anual 7.67% (IBGE) distribuído igualmente nos 12 meses | D9: =D8*(1+B9/100)
A10: 37012 | B10: 0.61774 | C10: Aproximação: IPCA anual 7.67% (IBGE) distribuído igualmente nos 12 meses | D10: =D9*(1+B10/100)
A11: 37043 | B11: 0.61774 | C11: Aproximação: IPCA anual 7.67% (IBGE) distribuído igualmente nos 12 meses | D11: =D10*(1+B11/100)
A12: 37073 | B12: 0.61774 | C12: Aproximação: IPCA anual 7.67% (IBGE) distribuído igualmente nos 12 meses | D12: =D11*(1+B12/100)
A13: 37104 | B13: 0.61774 | C13: Aproximação: IPCA anual 7.67% (IBGE) distribuído igualmente nos 12 meses | D13: =D12*(1+B13/100)
A14: 37135 | B14: 0.61774 | C14: Aproximação: IPCA anual 7.67% (IBGE) distribuído igualmente nos 12 meses | D14: =D13*(1+B14/100)
A15: 37165 | B15: 0.61774 | C15: Aproximação: IPCA anual 7.67% (IBGE) distribuído igualmente nos 12 meses | D15: =D14*(1+B15/100)
A16: 37196 | B16: 0.61774 | C16: Aproximação: IPCA anual 7.67% (IBGE) distribuído igualmente nos 12 meses | D16: =D15*(1+B16/100)
A17: 37226 | B17: 0.61774 | C17: Aproximação: IPCA anual 7.67% (IBGE) distribuído igualmente nos 12 meses | D17: =D16*(1+B17/100)
... A313: 46235 | B313: -0.32 | C313: IBGE - mensal oficial | D313: =D312*(1+B313/100)
A315: Conferência 2026 (IBGE): jan-abr acumulado 2,60%; jan-ago acumulado 3,11%. 2025 fechou em 4,26%.

Sheet Notas
A1: COMO FOI FEITO
A2: - Coluna D (FINAL) = extrato real sempre que existe. Valor original da base preservado na coluna F.
A3: - Extratos reais usados (Conta Corrente dos Representantes, só linhas TENDA): MFRUGIS05, 06, 08, 09, 10 e FRUGIS5 (2012 e jan/2013). Soma de cada extrato confere com o "Saldo do Periodo" impresso. FRUGIS1/FRUGIS2 são cópias do FRUGIS5 (não duplicados). FRUGIS.XLS e MFRUGIS11 não têm Tenda.
A4: - 2008 inclui o ajuste "DIF PERCENTUAL" (correção do % do Tenda); 2009 inclui a parte proporcional do "DIFERENCA".
A5: - Regra: pagamento do dia 15 = comissão do mês anterior (confere com 15/12/2005, 15/12/2006 e 15/12/2008).
A6: - 2007 (sem extrato): 2008 real ÷ (1 + IPCA 2008 = 5,90%).
A7: - Mantidos da base (sem extrato): pagamentos de 2001 a jan/2005 e de nov/2010 a jan/2012.
A8: - Complementado fev/2012 a ago/2026: extrato real até fev/2013; estimativa de mar/2013 a jun/2017 (média com variação); contas a pagar (pago à Frugis) a partir de jul/2017.
A9: - Valores estimados não são dados reais: identificar como estimativa no distrato.
