Workbook

Sheet Mensal
A1: Comissão mês a mês - Mario Frugis / FRUGIS REPRESENTAÇÕES (Tenda)
A2: Valores em R$. REAL = aba Lancamentos. ESTIMADO (laranja) = aba Estimativas. Distrato já pago fica fora.
A4: Competência | B4: Ano | C4: Mês | D4: Comissão (real) | E4: Prêmio (real) | F4: Total real | G4: Estimado | H4: Total comissão (real + estimado) | I4: Descontos | J4: Líquido pago | K4: Distrato pago (fora da base) | L4: Situação | M4: Saldo conta corrente - TODOS os clientes (ref.) | N4: % Tenda no saldo
A5: 38353 | B5: =YEAR(A5) | C5: =MONTH(A5) | D5: =SUMIFS(Lancamentos!$L$2:$L$2342,Lancamentos!$D$2:$D$2342,B5,Lancamentos!$E$2:$E$2342,C5)-E5 | E5: =SUMIFS(Lancamentos!$L$2:$L$2342,Lancamentos!$D$2:$D$2342,B5,Lancamentos!$E$2:$E$2342,C5,Lancamentos!$H$2:$H$2342,"PREMIO") | F5: =D5+E5 | G5: =SUMIFS(Estimativas!$F:$F,Estimativas!$A:$A,A5) | H5: =F5+G5 | I5: =SUMIFS(Lancamentos!$J$2:$J$2342,Lancamentos!$D$2:$D$2342,B5,Lancamentos!$E$2:$E$2342,C5,Lancamentos!$H$2:$H$2342,"<>DISTRATO") | J5: =F5-I5 | K5: =SUMIFS(Lancamentos!$K$2:$K$2342,Lancamentos!$D$2:$D$2342,B5,Lancamentos!$E$2:$E$2342,C5,Lancamentos!$H$2:$H$2342,"DISTRATO") | L5: Tenda (conta corrente) | M5: =IFERROR(INDEX(ContaCorrente!$D:$D,MATCH(A5,ContaCorrente!$A:$A,0)),"") | N5: =IF(AND(ISNUMBER(M5),M5<>0),F5/M5,"")
A6: 38384 | B6: =YEAR(A6) | C6: =MONTH(A6) | D6: =SUMIFS(Lancamentos!$L$2:$L$2342,Lancamentos!$D$2:$D$2342,B6,Lancamentos!$E$2:$E$2342,C6)-E6 | E6: =SUMIFS(Lancamentos!$L$2:$L$2342,Lancamentos!$D$2:$D$2342,B6,Lancamentos!$E$2:$E$2342,C6,Lancamentos!$H$2:$H$2342,"PREMIO") | F6: =D6+E6 | G6: =SUMIFS(Estimativas!$F:$F,Estimativas!$A:$A,A6) | H6: =F6+G6 | I6: =SUMIFS(Lancamentos!$J$2:$J$2342,Lancamentos!$D$2:$D$2342,B6,Lancamentos!$E$2:$E$2342,C6,Lancamentos!$H$2:$H$2342,"<>DISTRATO") | J6: =F6-I6 | K6: =SUMIFS(Lancamentos!$K$2:$K$2342,Lancamentos!$D$2:$D$2342,B6,Lancamentos!$E$2:$E$2342,C6,Lancamentos!$H$2:$H$2342,"DISTRATO") | L6: Tenda (conta corrente) | M6: =IFERROR(INDEX(ContaCorrente!$D:$D,MATCH(A6,ContaCorrente!$A:$A,0)),"") | N6: =IF(AND(ISNUMBER(M6),M6<>0),F6/M6,"")
A7: 38412 | B7: =YEAR(A7) | C7: =MONTH(A7) | D7: =SUMIFS(Lancamentos!$L$2:$L$2342,Lancamentos!$D$2:$D$2342,B7,Lancamentos!$E$2:$E$2342,C7)-E7 | E7: =SUMIFS(Lancamentos!$L$2:$L$2342,Lancamentos!$D$2:$D$2342,B7,Lancamentos!$E$2:$E$2342,C7,Lancamentos!$H$2:$H$2342,"PREMIO") | F7: =D7+E7 | G7: =SUMIFS(Estimativas!$F:$F,Estimativas!$A:$A,A7) | H7: =F7+G7 | I7: =SUMIFS(Lancamentos!$J$2:$J$2342,Lancamentos!$D$2:$D$2342,B7,Lancamentos!$E$2:$E$2342,C7,Lancamentos!$H$2:$H$2342,"<>DISTRATO") | J7: =F7-I7 | K7: =SUMIFS(Lancamentos!$K$2:$K$2342,Lancamentos!$D$2:$D$2342,B7,Lancamentos!$E$2:$E$2342,C7,Lancamentos!$H$2:$H$2342,"DISTRATO") | L7: Tenda (conta corrente) | M7: =IFERROR(INDEX(ContaCorrente!$D:$D,MATCH(A7,ContaCorrente!$A:$A,0)),"") | N7: =IF(AND(ISNUMBER(M7),M7<>0),F7/M7,"")
A8: 38443 | B8: =YEAR(A8) | C8: =MONTH(A8) | D8: =SUMIFS(Lancamentos!$L$2:$L$2342,Lancamentos!$D$2:$D$2342,B8,Lancamentos!$E$2:$E$2342,C8)-E8 | E8: =SUMIFS(Lancamentos!$L$2:$L$2342,Lancamentos!$D$2:$D$2342,B8,Lancamentos!$E$2:$E$2342,C8,Lancamentos!$H$2:$H$2342,"PREMIO") | F8: =D8+E8 | G8: =SUMIFS(Estimativas!$F:$F,Estimativas!$A:$A,A8) | H8: =F8+G8 | I8: =SUMIFS(Lancamentos!$J$2:$J$2342,Lancamentos!$D$2:$D$2342,B8,Lancamentos!$E$2:$E$2342,C8,Lancamentos!$H$2:$H$2342,"<>DISTRATO") | J8: =F8-I8 | K8: =SUMIFS(Lancamentos!$K$2:$K$2342,Lancamentos!$D$2:$D$2342,B8,Lancamentos!$E$2:$E$2342,C8,Lancamentos!$H$2:$H$2342,"DISTRATO") | L8: Tenda (conta corrente) | M8: =IFERROR(INDEX(ContaCorrente!$D:$D,MATCH(A8,ContaCorrente!$A:$A,0)),"") | N8: =IF(AND(ISNUMBER(M8),M8<>0),F8/M8,"")
A9: 38473 | B9: =YEAR(A9) | C9: =MONTH(A9) | D9: =SUMIFS(Lancamentos!$L$2:$L$2342,Lancamentos!$D$2:$D$2342,B9,Lancamentos!$E$2:$E$2342,C9)-E9 | E9: =SUMIFS(Lancamentos!$L$2:$L$2342,Lancamentos!$D$2:$D$2342,B9,Lancamentos!$E$2:$E$2342,C9,Lancamentos!$H$2:$H$2342,"PREMIO") | F9: =D9+E9 | G9: =SUMIFS(Estimativas!$F:$F,Estimativas!$A:$A,A9) | H9: =F9+G9 | I9: =SUMIFS(Lancamentos!$J$2:$J$2342,Lancamentos!$D$2:$D$2342,B9,Lancamentos!$E$2:$E$2342,C9,Lancamentos!$H$2:$H$2342,"<>DISTRATO") | J9: =F9-I9 | K9: =SUMIFS(Lancamentos!$K$2:$K$2342,Lancamentos!$D$2:$D$2342,B9,Lancamentos!$E$2:$E$2342,C9,Lancamentos!$H$2:$H$2342,"DISTRATO") | L9: Tenda (conta corrente) | M9: =IFERROR(INDEX(ContaCorrente!$D:$D,MATCH(A9,ContaCorrente!$A:$A,0)),"") | N9: =IF(AND(ISNUMBER(M9),M9<>0),F9/M9,"")
A10: 38504 | B10: =YEAR(A10) | C10: =MONTH(A10) | D10: =SUMIFS(Lancamentos!$L$2:$L$2342,Lancamentos!$D$2:$D$2342,B10,Lancamentos!$E$2:$E$2342,C10)-E10 | E10: =SUMIFS(Lancamentos!$L$2:$L$2342,Lancamentos!$D$2:$D$2342,B10,Lancamentos!$E$2:$E$2342,C10,Lancamentos!$H$2:$H$2342,"PREMIO") | F10: =D10+E10 | G10: =SUMIFS(Estimativas!$F:$F,Estimativas!$A:$A,A10) | H10: =F10+G10 | I10: =SUMIFS(Lancamentos!$J$2:$J$2342,Lancamentos!$D$2:$D$2342,B10,Lancamentos!$E$2:$E$2342,C10,Lancamentos!$H$2:$H$2342,"<>DISTRATO") | J10: =F10-I10 | K10: =SUMIFS(Lancamentos!$K$2:$K$2342,Lancamentos!$D$2:$D$2342,B10,Lancamentos!$E$2:$E$2342,C10,Lancamentos!$H$2:$H$2342,"DISTRATO") | L10: Tenda (conta corrente) | M10: =IFERROR(INDEX(ContaCorrente!$D:$D,MATCH(A10,ContaCorrente!$A:$A,0)),"") | N10: =IF(AND(ISNUMBER(M10),M10<>0),F10/M10,"")
A11: 38534 | B11: =YEAR(A11) | C11: =MONTH(A11) | D11: =SUMIFS(Lancamentos!$L$2:$L$2342,Lancamentos!$D$2:$D$2342,B11,Lancamentos!$E$2:$E$2342,C11)-E11 | E11: =SUMIFS(Lancamentos!$L$2:$L$2342,Lancamentos!$D$2:$D$2342,B11,Lancamentos!$E$2:$E$2342,C11,Lancamentos!$H$2:$H$2342,"PREMIO") | F11: =D11+E11 | G11: =SUMIFS(Estimativas!$F:$F,Estimativas!$A:$A,A11) | H11: =F11+G11 | I11: =SUMIFS(Lancamentos!$J$2:$J$2342,Lancamentos!$D$2:$D$2342,B11,Lancamentos!$E$2:$E$2342,C11,Lancamentos!$H$2:$H$2342,"<>DISTRATO") | J11: =F11-I11 | K11: =SUMIFS(Lancamentos!$K$2:$K$2342,Lancamentos!$D$2:$D$2342,B11,Lancamentos!$E$2:$E$2342,C11,Lancamentos!$H$2:$H$2342,"DISTRATO") | L11: Tenda (conta corrente) | M11: =IFERROR(INDEX(ContaCorrente!$D:$D,MATCH(A11,ContaCorrente!$A:$A,0)),"") | N11: =IF(AND(ISNUMBER(M11),M11<>0),F11/M11,"")
A12: 38565 | B12: =YEAR(A12) | C12: =MONTH(A12) | D12: =SUMIFS(Lancamentos!$L$2:$L$2342,Lancamentos!$D$2:$D$2342,B12,Lancamentos!$E$2:$E$2342,C12)-E12 | E12: =SUMIFS(Lancamentos!$L$2:$L$2342,Lancamentos!$D$2:$D$2342,B12,Lancamentos!$E$2:$E$2342,C12,Lancamentos!$H$2:$H$2342,"PREMIO") | F12: =D12+E12 | G12: =SUMIFS(Estimativas!$F:$F,Estimativas!$A:$A,A12) | H12: =F12+G12 | I12: =SUMIFS(Lancamentos!$J$2:$J$2342,Lancamentos!$D$2:$D$2342,B12,Lancamentos!$E$2:$E$2342,C12,Lancamentos!$H$2:$H$2342,"<>DISTRATO") | J12: =F12-I12 | K12: =SUMIFS(Lancamentos!$K$2:$K$2342,Lancamentos!$D$2:$D$2342,B12,Lancamentos!$E$2:$E$2342,C12,Lancamentos!$H$2:$H$2342,"DISTRATO") | L12: Tenda (conta corrente) | M12: =IFERROR(INDEX(ContaCorrente!$D:$D,MATCH(A12,ContaCorrente!$A:$A,0)),"") | N12: =IF(AND(ISNUMBER(M12),M12<>0),F12/M12,"")
A13: 38596 | B13: =YEAR(A13) | C13: =MONTH(A13) | D13: =SUMIFS(Lancamentos!$L$2:$L$2342,Lancamentos!$D$2:$D$2342,B13,Lancamentos!$E$2:$E$2342,C13)-E13 | E13: =SUMIFS(Lancamentos!$L$2:$L$2342,Lancamentos!$D$2:$D$2342,B13,Lancamentos!$E$2:$E$2342,C13,Lancamentos!$H$2:$H$2342,"PREMIO") | F13: =D13+E13 | G13: =SUMIFS(Estimativas!$F:$F,Estimativas!$A:$A,A13) | H13: =F13+G13 | I13: =SUMIFS(Lancamentos!$J$2:$J$2342,Lancamentos!$D$2:$D$2342,B13,Lancamentos!$E$2:$E$2342,C13,Lancamentos!$H$2:$H$2342,"<>DISTRATO") | J13: =F13-I13 | K13: =SUMIFS(Lancamentos!$K$2:$K$2342,Lancamentos!$D$2:$D$2342,B13,Lancamentos!$E$2:$E$2342,C13,Lancamentos!$H$2:$H$2342,"DISTRATO") | L13: Tenda (conta corrente) | M13: =IFERROR(INDEX(ContaCorrente!$D:$D,MATCH(A13,ContaCorrente!$A:$A,0)),"") | N13: =IF(AND(ISNUMBER(M13),M13<>0),F13/M13,"")
A14: 38626 | B14: =YEAR(A14) | C14: =MONTH(A14) | D14: =SUMIFS(Lancamentos!$L$2:$L$2342,Lancamentos!$D$2:$D$2342,B14,Lancamentos!$E$2:$E$2342,C14)-E14 | E14: =SUMIFS(Lancamentos!$L$2:$L$2342,Lancamentos!$D$2:$D$2342,B14,Lancamentos!$E$2:$E$2342,C14,Lancamentos!$H$2:$H$2342,"PREMIO") | F14: =D14+E14 | G14: =SUMIFS(Estimativas!$F:$F,Estimativas!$A:$A,A14) | H14: =F14+G14 | I14: =SUMIFS(Lancamentos!$J$2:$J$2342,Lancamentos!$D$2:$D$2342,B14,Lancamentos!$E$2:$E$2342,C14,Lancamentos!$H$2:$H$2342,"<>DISTRATO") | J14: =F14-I14 | K14: =SUMIFS(Lancamentos!$K$2:$K$2342,Lancamentos!$D$2:$D$2342,B14,Lancamentos!$E$2:$E$2342,C14,Lancamentos!$H$2:$H$2342,"DISTRATO") | L14: Tenda (conta corrente) | M14: =IFERROR(INDEX(ContaCorrente!$D:$D,MATCH(A14,ContaCorrente!$A:$A,0)),"") | N14: =IF(AND(ISNUMBER(M14),M14<>0),F14/M14,"")
A15: 38657 | B15: =YEAR(A15) | C15: =MONTH(A15) | D15: =SUMIFS(Lancamentos!$L$2:$L$2342,Lancamentos!$D$2:$D$2342,B15,Lancamentos!$E$2:$E$2342,C15)-E15 | E15: =SUMIFS(Lancamentos!$L$2:$L$2342,Lancamentos!$D$2:$D$2342,B15,Lancamentos!$E$2:$E$2342,C15,Lancamentos!$H$2:$H$2342,"PREMIO") | F15: =D15+E15 | G15: =SUMIFS(Estimativas!$F:$F,Estimativas!$A:$A,A15) | H15: =F15+G15 | I15: =SUMIFS(Lancamentos!$J$2:$J$2342,Lancamentos!$D$2:$D$2342,B15,Lancamentos!$E$2:$E$2342,C15,Lancamentos!$H$2:$H$2342,"<>DISTRATO") | J15: =F15-I15 | K15: =SUMIFS(Lancamentos!$K$2:$K$2342,Lancamentos!$D$2:$D$2342,B15,Lancamentos!$E$2:$E$2342,C15,Lancamentos!$H$2:$H$2342,"DISTRATO") | L15: Tenda (conta corrente) | M15: =IFERROR(INDEX(ContaCorrente!$D:$D,MATCH(A15,ContaCorrente!$A:$A,0)),"") | N15: =IF(AND(ISNUMBER(M15),M15<>0),F15/M15,"")
A16: 38687 | B16: =YEAR(A16) | C16: =MONTH(A16) | D16: =SUMIFS(Lancamentos!$L$2:$L$2342,Lancamentos!$D$2:$D$2342,B16,Lancamentos!$E$2:$E$2342,C16)-E16 | E16: =SUMIFS(Lancamentos!$L$2:$L$2342,Lancamentos!$D$2:$D$2342,B16,Lancamentos!$E$2:$E$2342,C16,Lancamentos!$H$2:$H$2342,"PREMIO") | F16: =D16+E16 | G16: =SUMIFS(Estimativas!$F:$F,Estimativas!$A:$A,A16) | H16: =F16+G16 | I16: =SUMIFS(Lancamentos!$J$2:$J$2342,Lancamentos!$D$2:$D$2342,B16,Lancamentos!$E$2:$E$2342,C16,Lancamentos!$H$2:$H$2342,"<>DISTRATO") | J16: =F16-I16 | K16: =SUMIFS(Lancamentos!$K$2:$K$2342,Lancamentos!$D$2:$D$2342,B16,Lancamentos!$E$2:$E$2342,C16,Lancamentos!$H$2:$H$2342,"DISTRATO") | L16: Tenda (conta corrente) | M16: =IFERROR(INDEX(ContaCorrente!$D:$D,MATCH(A16,ContaCorrente!$A:$A,0)),"") | N16: =IF(AND(ISNUMBER(M16),M16<>0),F16/M16,"")
... A263: 46204 | B263: =YEAR(A263) | C263: =MONTH(A263) | D263: =SUMIFS(Lancamentos!$L$2:$L$2342,Lancamentos!$D$2:$D$2342,B263,Lancamentos!$E$2:$E$2342,C263)-E263 | E263: =SUMIFS(Lancamentos!$L$2:$L$2342,Lancamentos!$D$2:$D$2342,B263,Lancamentos!$E$2:$E$2342,C263,Lancamentos!$H$2:$H$2342,"PREMIO") | F263: =D263+E263 | G263: =SUMIFS(Estimativas!$F:$F,Estimativas!$A:$A,A263) | H263: =F263+G263 | I263: =SUMIFS(Lancamentos!$J$2:$J$2342,Lancamentos!$D$2:$D$2342,B263,Lancamentos!$E$2:$E$2342,C263,Lancamentos!$H$2:$H$2342,"<>DISTRATO") | J263: =F263-I263 | K263: =SUMIFS(Lancamentos!$K$2:$K$2342,Lancamentos!$D$2:$D$2342,B263,Lancamentos!$E$2:$E$2342,C263,Lancamentos!$H$2:$H$2342,"DISTRATO") | L263: Pago | M263: =IFERROR(INDEX(ContaCorrente!$D:$D,MATCH(A263,ContaCorrente!$A:$A,0)),"") | N263: =IF(AND(ISNUMBER(M263),M263<>0),F263/M263,"")
A264: TOTAL | D264: =SUM(D5:D263) | E264: =SUM(E5:E263) | F264: =SUM(F5:F263) | G264: =SUM(G5:G263) | H264: =SUM(H5:H263) | I264: =SUM(I5:I263) | J264: =SUM(J5:J263) | K264: =SUM(K5:K263)
A266: Total REAL | H266: =F264
A267: Total ESTIMADO | H267: =G264
A268: % estimado | H268: =IF(H264=0,0,G264/H264)
A269: Conferência: total da aba Lancamentos - Total real (deve ser zero) | H269: =Lancamentos!L2343-F264

Sheet Origem dos Valores
A1: De onde vem cada valor (só Tenda) - real x estimado, por ano de competência
A3: Ano | B3: Extrato real Tenda (conta corrente) | C3: Contas a pagar (pago à Frugis) | D3: ESTIMADO | E3: Total | F3: % estimado | G3: Como foi estimado
A4: 2005 | B4: =SUMIFS(Mensal!$F$5:$F$263,Mensal!$B$5:$B$263,A4,Mensal!$L$5:$L$263,"Tenda*") | C4: =SUMIFS(Mensal!$F$5:$F$263,Mensal!$B$5:$B$263,A4,Mensal!$L$5:$L$263,"Pago") | D4: =SUMIFS(Mensal!$G$5:$G$263,Mensal!$B$5:$B$263,A4) | E4: =B4+C4+D4 | F4: =IF(E4=0,"",D4/E4) | G4: —
A5: 2006 | B5: =SUMIFS(Mensal!$F$5:$F$263,Mensal!$B$5:$B$263,A5,Mensal!$L$5:$L$263,"Tenda*") | C5: =SUMIFS(Mensal!$F$5:$F$263,Mensal!$B$5:$B$263,A5,Mensal!$L$5:$L$263,"Pago") | D5: =SUMIFS(Mensal!$G$5:$G$263,Mensal!$B$5:$B$263,A5) | E5: =B5+C5+D5 | F5: =IF(E5=0,"",D5/E5) | G5: —
A6: 2007 | B6: =SUMIFS(Mensal!$F$5:$F$263,Mensal!$B$5:$B$263,A6,Mensal!$L$5:$L$263,"Tenda*") | C6: =SUMIFS(Mensal!$F$5:$F$263,Mensal!$B$5:$B$263,A6,Mensal!$L$5:$L$263,"Pago") | D6: =SUMIFS(Mensal!$G$5:$G$263,Mensal!$B$5:$B$263,A6) | E6: =B6+C6+D6 | F6: =IF(E6=0,"",D6/E6) | G6: 2008 real ÷ IPCA 2008 (5,90%)
A7: 2008 | B7: =SUMIFS(Mensal!$F$5:$F$263,Mensal!$B$5:$B$263,A7,Mensal!$L$5:$L$263,"Tenda*") | C7: =SUMIFS(Mensal!$F$5:$F$263,Mensal!$B$5:$B$263,A7,Mensal!$L$5:$L$263,"Pago") | D7: =SUMIFS(Mensal!$G$5:$G$263,Mensal!$B$5:$B$263,A7) | E7: =B7+C7+D7 | F7: =IF(E7=0,"",D7/E7) | G7: —
A8: 2009 | B8: =SUMIFS(Mensal!$F$5:$F$263,Mensal!$B$5:$B$263,A8,Mensal!$L$5:$L$263,"Tenda*") | C8: =SUMIFS(Mensal!$F$5:$F$263,Mensal!$B$5:$B$263,A8,Mensal!$L$5:$L$263,"Pago") | D8: =SUMIFS(Mensal!$G$5:$G$263,Mensal!$B$5:$B$263,A8) | E8: =B8+C8+D8 | F8: =IF(E8=0,"",D8/E8) | G8: —
A9: 2010 | B9: =SUMIFS(Mensal!$F$5:$F$263,Mensal!$B$5:$B$263,A9,Mensal!$L$5:$L$263,"Tenda*") | C9: =SUMIFS(Mensal!$F$5:$F$263,Mensal!$B$5:$B$263,A9,Mensal!$L$5:$L$263,"Pago") | D9: =SUMIFS(Mensal!$G$5:$G$263,Mensal!$B$5:$B$263,A9) | E9: =B9+C9+D9 | F9: =IF(E9=0,"",D9/E9) | G9: out-dez: média c/ variação
A10: 2011 | B10: =SUMIFS(Mensal!$F$5:$F$263,Mensal!$B$5:$B$263,A10,Mensal!$L$5:$L$263,"Tenda*") | C10: =SUMIFS(Mensal!$F$5:$F$263,Mensal!$B$5:$B$263,A10,Mensal!$L$5:$L$263,"Pago") | D10: =SUMIFS(Mensal!$G$5:$G$263,Mensal!$B$5:$B$263,A10) | E10: =B10+C10+D10 | F10: =IF(E10=0,"",D10/E10) | G10: média c/ variação
A11: 2012 | B11: =SUMIFS(Mensal!$F$5:$F$263,Mensal!$B$5:$B$263,A11,Mensal!$L$5:$L$263,"Tenda*") | C11: =SUMIFS(Mensal!$F$5:$F$263,Mensal!$B$5:$B$263,A11,Mensal!$L$5:$L$263,"Pago") | D11: =SUMIFS(Mensal!$G$5:$G$263,Mensal!$B$5:$B$263,A11) | E11: =B11+C11+D11 | F11: =IF(E11=0,"",D11/E11) | G11: —
A12: 2013 | B12: =SUMIFS(Mensal!$F$5:$F$263,Mensal!$B$5:$B$263,A12,Mensal!$L$5:$L$263,"Tenda*") | C12: =SUMIFS(Mensal!$F$5:$F$263,Mensal!$B$5:$B$263,A12,Mensal!$L$5:$L$263,"Pago") | D12: =SUMIFS(Mensal!$G$5:$G$263,Mensal!$B$5:$B$263,A12) | E12: =B12+C12+D12 | F12: =IF(E12=0,"",D12/E12) | G12: fev-dez: média c/ variação
A13: 2014 | B13: =SUMIFS(Mensal!$F$5:$F$263,Mensal!$B$5:$B$263,A13,Mensal!$L$5:$L$263,"Tenda*") | C13: =SUMIFS(Mensal!$F$5:$F$263,Mensal!$B$5:$B$263,A13,Mensal!$L$5:$L$263,"Pago") | D13: =SUMIFS(Mensal!$G$5:$G$263,Mensal!$B$5:$B$263,A13) | E13: =B13+C13+D13 | F13: =IF(E13=0,"",D13/E13) | G13: média c/ variação
A14: 2015 | B14: =SUMIFS(Mensal!$F$5:$F$263,Mensal!$B$5:$B$263,A14,Mensal!$L$5:$L$263,"Tenda*") | C14: =SUMIFS(Mensal!$F$5:$F$263,Mensal!$B$5:$B$263,A14,Mensal!$L$5:$L$263,"Pago") | D14: =SUMIFS(Mensal!$G$5:$G$263,Mensal!$B$5:$B$263,A14) | E14: =B14+C14+D14 | F14: =IF(E14=0,"",D14/E14) | G14: média c/ variação
A15: 2016 | B15: =SUMIFS(Mensal!$F$5:$F$263,Mensal!$B$5:$B$263,A15,Mensal!$L$5:$L$263,"Tenda*") | C15: =SUMIFS(Mensal!$F$5:$F$263,Mensal!$B$5:$B$263,A15,Mensal!$L$5:$L$263,"Pago") | D15: =SUMIFS(Mensal!$G$5:$G$263,Mensal!$B$5:$B$263,A15) | E15: =B15+C15+D15 | F15: =IF(E15=0,"",D15/E15) | G15: média c/ variação
... A25: 2026 | B25: =SUMIFS(Mensal!$F$5:$F$263,Mensal!$B$5:$B$263,A25,Mensal!$L$5:$L$263,"Tenda*") | C25: =SUMIFS(Mensal!$F$5:$F$263,Mensal!$B$5:$B$263,A25,Mensal!$L$5:$L$263,"Pago") | D25: =SUMIFS(Mensal!$G$5:$G$263,Mensal!$B$5:$B$263,A25) | E25: =B25+C25+D25 | F25: =IF(E25=0,"",D25/E25) | G25: —
A26: TOTAL | B26: =SUM(B4:B25) | C26: =SUM(C4:C25) | D26: =SUM(D4:D25) | E26: =SUM(E4:E25) | F26: =IF(E26=0,"",D26/E26)
A28: Períodos estimados
A29: Período (competência) | B29: Meses | C29: Método | D29: Valor estimado
A30: jan-dez/2007 | B30: 12 | C30: Mesmo mês de 2008 real ÷ (1+IPCA 2008) | D30: =SUMIFS(Mensal!$G$5:$G$263,Mensal!$A$5:$A$263,">="&DATE(2007,1,1),Mensal!$A$5:$A$263,"<="&DATE(2007,12,1))
A31: out/2010-dez/2011 | B31: 15 | C31: Média do Tenda real antes/depois, variação aleatória ±15% | D31: =SUMIFS(Mensal!$G$5:$G$263,Mensal!$A$5:$A$263,">="&DATE(2010,10,1),Mensal!$A$5:$A$263,"<="&DATE(2011,12,1))
A32: fev/2013-mai/2017 | B32: 52 | C32: Média do Tenda 2012 até pagamentos 2017/2018, variação aleatória ±15% | D32: =SUMIFS(Mensal!$G$5:$G$263,Mensal!$A$5:$A$263,">="&DATE(2013,2,1),Mensal!$A$5:$A$263,"<="&DATE(2017,5,1))
A33: TOTAL | B33: =SUM(B30:B32) | D33: =SUM(D30:D32)

Sheet Resumo Anual
A1: Comissão total (real + estimado) por ano e mês (R$)
A3: Ano | B3: Jan | C3: Fev | D3: Mar | E3: Abr | F3: Mai | G3: Jun | H3: Jul | I3: Ago | J3: Set | K3: Out | L3: Nov | M3: Dez | N3: Total
A4: 2005 | B4: =SUMIFS(Mensal!$H$5:$H$263,Mensal!$B$5:$B$263,$A4,Mensal!$C$5:$C$263,1) | C4: =SUMIFS(Mensal!$H$5:$H$263,Mensal!$B$5:$B$263,$A4,Mensal!$C$5:$C$263,2) | D4: =SUMIFS(Mensal!$H$5:$H$263,Mensal!$B$5:$B$263,$A4,Mensal!$C$5:$C$263,3) | E4: =SUMIFS(Mensal!$H$5:$H$263,Mensal!$B$5:$B$263,$A4,Mensal!$C$5:$C$263,4) | F4: =SUMIFS(Mensal!$H$5:$H$263,Mensal!$B$5:$B$263,$A4,Mensal!$C$5:$C$263,5) | G4: =SUMIFS(Mensal!$H$5:$H$263,Mensal!$B$5:$B$263,$A4,Mensal!$C$5:$C$263,6) | H4: =SUMIFS(Mensal!$H$5:$H$263,Mensal!$B$5:$B$263,$A4,Mensal!$C$5:$C$263,7) | I4: =SUMIFS(Mensal!$H$5:$H$263,Mensal!$B$5:$B$263,$A4,Mensal!$C$5:$C$263,8) | J4: =SUMIFS(Mensal!$H$5:$H$263,Mensal!$B$5:$B$263,$A4,Mensal!$C$5:$C$263,9) | K4: =SUMIFS(Mensal!$H$5:$H$263,Mensal!$B$5:$B$263,$A4,Mensal!$C$5:$C$263,10) | L4: =SUMIFS(Mensal!$H$5:$H$263,Mensal!$B$5:$B$263,$A4,Mensal!$C$5:$C$263,11) | M4: =SUMIFS(Mensal!$H$5:$H$263,Mensal!$B$5:$B$263,$A4,Mensal!$C$5:$C$263,12) | N4: =SUM(B4:M4)
A5: 2006 | B5: =SUMIFS(Mensal!$H$5:$H$263,Mensal!$B$5:$B$263,$A5,Mensal!$C$5:$C$263,1) | C5: =SUMIFS(Mensal!$H$5:$H$263,Mensal!$B$5:$B$263,$A5,Mensal!$C$5:$C$263,2) | D5: =SUMIFS(Mensal!$H$5:$H$263,Mensal!$B$5:$B$263,$A5,Mensal!$C$5:$C$263,3) | E5: =SUMIFS(Mensal!$H$5:$H$263,Mensal!$B$5:$B$263,$A5,Mensal!$C$5:$C$263,4) | F5: =SUMIFS(Mensal!$H$5:$H$263,Mensal!$B$5:$B$263,$A5,Mensal!$C$5:$C$263,5) | G5: =SUMIFS(Mensal!$H$5:$H$263,Mensal!$B$5:$B$263,$A5,Mensal!$C$5:$C$263,6) | H5: =SUMIFS(Mensal!$H$5:$H$263,Mensal!$B$5:$B$263,$A5,Mensal!$C$5:$C$263,7) | I5: =SUMIFS(Mensal!$H$5:$H$263,Mensal!$B$5:$B$263,$A5,Mensal!$C$5:$C$263,8) | J5: =SUMIFS(Mensal!$H$5:$H$263,Mensal!$B$5:$B$263,$A5,Mensal!$C$5:$C$263,9) | K5: =SUMIFS(Mensal!$H$5:$H$263,Mensal!$B$5:$B$263,$A5,Mensal!$C$5:$C$263,10) | L5: =SUMIFS(Mensal!$H$5:$H$263,Mensal!$B$5:$B$263,$A5,Mensal!$C$5:$C$263,11) | M5: =SUMIFS(Mensal!$H$5:$H$263,Mensal!$B$5:$B$263,$A5,Mensal!$C$5:$C$263,12) | N5: =SUM(B5:M5)
A6: 2007 | B6: =SUMIFS(Mensal!$H$5:$H$263,Mensal!$B$5:$B$263,$A6,Mensal!$C$5:$C$263,1) | C6: =SUMIFS(Mensal!$H$5:$H$263,Mensal!$B$5:$B$263,$A6,Mensal!$C$5:$C$263,2) | D6: =SUMIFS(Mensal!$H$5:$H$263,Mensal!$B$5:$B$263,$A6,Mensal!$C$5:$C$263,3) | E6: =SUMIFS(Mensal!$H$5:$H$263,Mensal!$B$5:$B$263,$A6,Mensal!$C$5:$C$263,4) | F6: =SUMIFS(Mensal!$H$5:$H$263,Mensal!$B$5:$B$263,$A6,Mensal!$C$5:$C$263,5) | G6: =SUMIFS(Mensal!$H$5:$H$263,Mensal!$B$5:$B$263,$A6,Mensal!$C$5:$C$263,6) | H6: =SUMIFS(Mensal!$H$5:$H$263,Mensal!$B$5:$B$263,$A6,Mensal!$C$5:$C$263,7) | I6: =SUMIFS(Mensal!$H$5:$H$263,Mensal!$B$5:$B$263,$A6,Mensal!$C$5:$C$263,8) | J6: =SUMIFS(Mensal!$H$5:$H$263,Mensal!$B$5:$B$263,$A6,Mensal!$C$5:$C$263,9) | K6: =SUMIFS(Mensal!$H$5:$H$263,Mensal!$B$5:$B$263,$A6,Mensal!$C$5:$C$263,10) | L6: =SUMIFS(Mensal!$H$5:$H$263,Mensal!$B$5:$B$263,$A6,Mensal!$C$5:$C$263,11) | M6: =SUMIFS(Mensal!$H$5:$H$263,Mensal!$B$5:$B$263,$A6,Mensal!$C$5:$C$263,12) | N6: =SUM(B6:M6)
A7: 2008 | B7: =SUMIFS(Mensal!$H$5:$H$263,Mensal!$B$5:$B$263,$A7,Mensal!$C$5:$C$263,1) | C7: =SUMIFS(Mensal!$H$5:$H$263,Mensal!$B$5:$B$263,$A7,Mensal!$C$5:$C$263,2) | D7: =SUMIFS(Mensal!$H$5:$H$263,Mensal!$B$5:$B$263,$A7,Mensal!$C$5:$C$263,3) | E7: =SUMIFS(Mensal!$H$5:$H$263,Mensal!$B$5:$B$263,$A7,Mensal!$C$5:$C$263,4) | F7: =SUMIFS(Mensal!$H$5:$H$263,Mensal!$B$5:$B$263,$A7,Mensal!$C$5:$C$263,5) | G7: =SUMIFS(Mensal!$H$5:$H$263,Mensal!$B$5:$B$263,$A7,Mensal!$C$5:$C$263,6) | H7: =SUMIFS(Mensal!$H$5:$H$263,Mensal!$B$5:$B$263,$A7,Mensal!$C$5:$C$263,7) | I7: =SUMIFS(Mensal!$H$5:$H$263,Mensal!$B$5:$B$263,$A7,Mensal!$C$5:$C$263,8) | J7: =SUMIFS(Mensal!$H$5:$H$263,Mensal!$B$5:$B$263,$A7,Mensal!$C$5:$C$263,9) | K7: =SUMIFS(Mensal!$H$5:$H$263,Mensal!$B$5:$B$263,$A7,Mensal!$C$5:$C$263,10) | L7: =SUMIFS(Mensal!$H$5:$H$263,Mensal!$B$5:$B$263,$A7,Mensal!$C$5:$C$263,11) | M7: =SUMIFS(Mensal!$H$5:$H$263,Mensal!$B$5:$B$263,$A7,Mensal!$C$5:$C$263,12) | N7: =SUM(B7:M7)
A8: 2009 | B8: =SUMIFS(Mensal!$H$5:$H$263,Mensal!$B$5:$B$263,$A8,Mensal!$C$5:$C$263,1) | C8: =SUMIFS(Mensal!$H$5:$H$263,Mensal!$B$5:$B$263,$A8,Mensal!$C$5:$C$263,2) | D8: =SUMIFS(Mensal!$H$5:$H$263,Mensal!$B$5:$B$263,$A8,Mensal!$C$5:$C$263,3) | E8: =SUMIFS(Mensal!$H$5:$H$263,Mensal!$B$5:$B$263,$A8,Mensal!$C$5:$C$263,4) | F8: =SUMIFS(Mensal!$H$5:$H$263,Mensal!$B$5:$B$263,$A8,Mensal!$C$5:$C$263,5) | G8: =SUMIFS(Mensal!$H$5:$H$263,Mensal!$B$5:$B$263,$A8,Mensal!$C$5:$C$263,6) | H8: =SUMIFS(Mensal!$H$5:$H$263,Mensal!$B$5:$B$263,$A8,Mensal!$C$5:$C$263,7) | I8: =SUMIFS(Mensal!$H$5:$H$263,Mensal!$B$5:$B$263,$A8,Mensal!$C$5:$C$263,8) | J8: =SUMIFS(Mensal!$H$5:$H$263,Mensal!$B$5:$B$263,$A8,Mensal!$C$5:$C$263,9) | K8: =SUMIFS(Mensal!$H$5:$H$263,Mensal!$B$5:$B$263,$A8,Mensal!$C$5:$C$263,10) | L8: =SUMIFS(Mensal!$H$5:$H$263,Mensal!$B$5:$B$263,$A8,Mensal!$C$5:$C$263,11) | M8: =SUMIFS(Mensal!$H$5:$H$263,Mensal!$B$5:$B$263,$A8,Mensal!$C$5:$C$263,12) | N8: =SUM(B8:M8)
A9: 2010 | B9: =SUMIFS(Mensal!$H$5:$H$263,Mensal!$B$5:$B$263,$A9,Mensal!$C$5:$C$263,1) | C9: =SUMIFS(Mensal!$H$5:$H$263,Mensal!$B$5:$B$263,$A9,Mensal!$C$5:$C$263,2) | D9: =SUMIFS(Mensal!$H$5:$H$263,Mensal!$B$5:$B$263,$A9,Mensal!$C$5:$C$263,3) | E9: =SUMIFS(Mensal!$H$5:$H$263,Mensal!$B$5:$B$263,$A9,Mensal!$C$5:$C$263,4) | F9: =SUMIFS(Mensal!$H$5:$H$263,Mensal!$B$5:$B$263,$A9,Mensal!$C$5:$C$263,5) | G9: =SUMIFS(Mensal!$H$5:$H$263,Mensal!$B$5:$B$263,$A9,Mensal!$C$5:$C$263,6) | H9: =SUMIFS(Mensal!$H$5:$H$263,Mensal!$B$5:$B$263,$A9,Mensal!$C$5:$C$263,7) | I9: =SUMIFS(Mensal!$H$5:$H$263,Mensal!$B$5:$B$263,$A9,Mensal!$C$5:$C$263,8) | J9: =SUMIFS(Mensal!$H$5:$H$263,Mensal!$B$5:$B$263,$A9,Mensal!$C$5:$C$263,9) | K9: =SUMIFS(Mensal!$H$5:$H$263,Mensal!$B$5:$B$263,$A9,Mensal!$C$5:$C$263,10) | L9: =SUMIFS(Mensal!$H$5:$H$263,Mensal!$B$5:$B$263,$A9,Mensal!$C$5:$C$263,11) | M9: =SUMIFS(Mensal!$H$5:$H$263,Mensal!$B$5:$B$263,$A9,Mensal!$C$5:$C$263,12) | N9: =SUM(B9:M9)
A10: 2011 | B10: =SUMIFS(Mensal!$H$5:$H$263,Mensal!$B$5:$B$263,$A10,Mensal!$C$5:$C$263,1) | C10: =SUMIFS(Mensal!$H$5:$H$263,Mensal!$B$5:$B$263,$A10,Mensal!$C$5:$C$263,2) | D10: =SUMIFS(Mensal!$H$5:$H$263,Mensal!$B$5:$B$263,$A10,Mensal!$C$5:$C$263,3) | E10: =SUMIFS(Mensal!$H$5:$H$263,Mensal!$B$5:$B$263,$A10,Mensal!$C$5:$C$263,4) | F10: =SUMIFS(Mensal!$H$5:$H$263,Mensal!$B$5:$B$263,$A10,Mensal!$C$5:$C$263,5) | G10: =SUMIFS(Mensal!$H$5:$H$263,Mensal!$B$5:$B$263,$A10,Mensal!$C$5:$C$263,6) | H10: =SUMIFS(Mensal!$H$5:$H$263,Mensal!$B$5:$B$263,$A10,Mensal!$C$5:$C$263,7) | I10: =SUMIFS(Mensal!$H$5:$H$263,Mensal!$B$5:$B$263,$A10,Mensal!$C$5:$C$263,8) | J10: =SUMIFS(Mensal!$H$5:$H$263,Mensal!$B$5:$B$263,$A10,Mensal!$C$5:$C$263,9) | K10: =SUMIFS(Mensal!$H$5:$H$263,Mensal!$B$5:$B$263,$A10,Mensal!$C$5:$C$263,10) | L10: =SUMIFS(Mensal!$H$5:$H$263,Mensal!$B$5:$B$263,$A10,Mensal!$C$5:$C$263,11) | M10: =SUMIFS(Mensal!$H$5:$H$263,Mensal!$B$5:$B$263,$A10,Mensal!$C$5:$C$263,12) | N10: =SUM(B10:M10)
A11: 2012 | B11: =SUMIFS(Mensal!$H$5:$H$263,Mensal!$B$5:$B$263,$A11,Mensal!$C$5:$C$263,1) | C11: =SUMIFS(Mensal!$H$5:$H$263,Mensal!$B$5:$B$263,$A11,Mensal!$C$5:$C$263,2) | D11: =SUMIFS(Mensal!$H$5:$H$263,Mensal!$B$5:$B$263,$A11,Mensal!$C$5:$C$263,3) | E11: =SUMIFS(Mensal!$H$5:$H$263,Mensal!$B$5:$B$263,$A11,Mensal!$C$5:$C$263,4) | F11: =SUMIFS(Mensal!$H$5:$H$263,Mensal!$B$5:$B$263,$A11,Mensal!$C$5:$C$263,5) | G11: =SUMIFS(Mensal!$H$5:$H$263,Mensal!$B$5:$B$263,$A11,Mensal!$C$5:$C$263,6) | H11: =SUMIFS(Mensal!$H$5:$H$263,Mensal!$B$5:$B$263,$A11,Mensal!$C$5:$C$263,7) | I11: =SUMIFS(Mensal!$H$5:$H$263,Mensal!$B$5:$B$263,$A11,Mensal!$C$5:$C$263,8) | J11: =SUMIFS(Mensal!$H$5:$H$263,Mensal!$B$5:$B$263,$A11,Mensal!$C$5:$C$263,9) | K11: =SUMIFS(Mensal!$H$5:$H$263,Mensal!$B$5:$B$263,$A11,Mensal!$C$5:$C$263,10) | L11: =SUMIFS(Mensal!$H$5:$H$263,Mensal!$B$5:$B$263,$A11,Mensal!$C$5:$C$263,11) | M11: =SUMIFS(Mensal!$H$5:$H$263,Mensal!$B$5:$B$263,$A11,Mensal!$C$5:$C$263,12) | N11: =SUM(B11:M11)
A12: 2013 | B12: =SUMIFS(Mensal!$H$5:$H$263,Mensal!$B$5:$B$263,$A12,Mensal!$C$5:$C$263,1) | C12: =SUMIFS(Mensal!$H$5:$H$263,Mensal!$B$5:$B$263,$A12,Mensal!$C$5:$C$263,2) | D12: =SUMIFS(Mensal!$H$5:$H$263,Mensal!$B$5:$B$263,$A12,Mensal!$C$5:$C$263,3) | E12: =SUMIFS(Mensal!$H$5:$H$263,Mensal!$B$5:$B$263,$A12,Mensal!$C$5:$C$263,4) | F12: =SUMIFS(Mensal!$H$5:$H$263,Mensal!$B$5:$B$263,$A12,Mensal!$C$5:$C$263,5) | G12: =SUMIFS(Mensal!$H$5:$H$263,Mensal!$B$5:$B$263,$A12,Mensal!$C$5:$C$263,6) | H12: =SUMIFS(Mensal!$H$5:$H$263,Mensal!$B$5:$B$263,$A12,Mensal!$C$5:$C$263,7) | I12: =SUMIFS(Mensal!$H$5:$H$263,Mensal!$B$5:$B$263,$A12,Mensal!$C$5:$C$263,8) | J12: =SUMIFS(Mensal!$H$5:$H$263,Mensal!$B$5:$B$263,$A12,Mensal!$C$5:$C$263,9) | K12: =SUMIFS(Mensal!$H$5:$H$263,Mensal!$B$5:$B$263,$A12,Mensal!$C$5:$C$263,10) | L12: =SUMIFS(Mensal!$H$5:$H$263,Mensal!$B$5:$B$263,$A12,Mensal!$C$5:$C$263,11) | M12: =SUMIFS(Mensal!$H$5:$H$263,Mensal!$B$5:$B$263,$A12,Mensal!$C$5:$C$263,12) | N12: =SUM(B12:M12)
A13: 2014 | B13: =SUMIFS(Mensal!$H$5:$H$263,Mensal!$B$5:$B$263,$A13,Mensal!$C$5:$C$263,1) | C13: =SUMIFS(Mensal!$H$5:$H$263,Mensal!$B$5:$B$263,$A13,Mensal!$C$5:$C$263,2) | D13: =SUMIFS(Mensal!$H$5:$H$263,Mensal!$B$5:$B$263,$A13,Mensal!$C$5:$C$263,3) | E13: =SUMIFS(Mensal!$H$5:$H$263,Mensal!$B$5:$B$263,$A13,Mensal!$C$5:$C$263,4) | F13: =SUMIFS(Mensal!$H$5:$H$263,Mensal!$B$5:$B$263,$A13,Mensal!$C$5:$C$263,5) | G13: =SUMIFS(Mensal!$H$5:$H$263,Mensal!$B$5:$B$263,$A13,Mensal!$C$5:$C$263,6) | H13: =SUMIFS(Mensal!$H$5:$H$263,Mensal!$B$5:$B$263,$A13,Mensal!$C$5:$C$263,7) | I13: =SUMIFS(Mensal!$H$5:$H$263,Mensal!$B$5:$B$263,$A13,Mensal!$C$5:$C$263,8) | J13: =SUMIFS(Mensal!$H$5:$H$263,Mensal!$B$5:$B$263,$A13,Mensal!$C$5:$C$263,9) | K13: =SUMIFS(Mensal!$H$5:$H$263,Mensal!$B$5:$B$263,$A13,Mensal!$C$5:$C$263,10) | L13: =SUMIFS(Mensal!$H$5:$H$263,Mensal!$B$5:$B$263,$A13,Mensal!$C$5:$C$263,11) | M13: =SUMIFS(Mensal!$H$5:$H$263,Mensal!$B$5:$B$263,$A13,Mensal!$C$5:$C$263,12) | N13: =SUM(B13:M13)
A14: 2015 | B14: =SUMIFS(Mensal!$H$5:$H$263,Mensal!$B$5:$B$263,$A14,Mensal!$C$5:$C$263,1) | C14: =SUMIFS(Mensal!$H$5:$H$263,Mensal!$B$5:$B$263,$A14,Mensal!$C$5:$C$263,2) | D14: =SUMIFS(Mensal!$H$5:$H$263,Mensal!$B$5:$B$263,$A14,Mensal!$C$5:$C$263,3) | E14: =SUMIFS(Mensal!$H$5:$H$263,Mensal!$B$5:$B$263,$A14,Mensal!$C$5:$C$263,4) | F14: =SUMIFS(Mensal!$H$5:$H$263,Mensal!$B$5:$B$263,$A14,Mensal!$C$5:$C$263,5) | G14: =SUMIFS(Mensal!$H$5:$H$263,Mensal!$B$5:$B$263,$A14,Mensal!$C$5:$C$263,6) | H14: =SUMIFS(Mensal!$H$5:$H$263,Mensal!$B$5:$B$263,$A14,Mensal!$C$5:$C$263,7) | I14: =SUMIFS(Mensal!$H$5:$H$263,Mensal!$B$5:$B$263,$A14,Mensal!$C$5:$C$263,8) | J14: =SUMIFS(Mensal!$H$5:$H$263,Mensal!$B$5:$B$263,$A14,Mensal!$C$5:$C$263,9) | K14: =SUMIFS(Mensal!$H$5:$H$263,Mensal!$B$5:$B$263,$A14,Mensal!$C$5:$C$263,10) | L14: =SUMIFS(Mensal!$H$5:$H$263,Mensal!$B$5:$B$263,$A14,Mensal!$C$5:$C$263,11) | M14: =SUMIFS(Mensal!$H$5:$H$263,Mensal!$B$5:$B$263,$A14,Mensal!$C$5:$C$263,12) | N14: =SUM(B14:M14)
A15: 2016 | B15: =SUMIFS(Mensal!$H$5:$H$263,Mensal!$B$5:$B$263,$A15,Mensal!$C$5:$C$263,1) | C15: =SUMIFS(Mensal!$H$5:$H$263,Mensal!$B$5:$B$263,$A15,Mensal!$C$5:$C$263,2) | D15: =SUMIFS(Mensal!$H$5:$H$263,Mensal!$B$5:$B$263,$A15,Mensal!$C$5:$C$263,3) | E15: =SUMIFS(Mensal!$H$5:$H$263,Mensal!$B$5:$B$263,$A15,Mensal!$C$5:$C$263,4) | F15: =SUMIFS(Mensal!$H$5:$H$263,Mensal!$B$5:$B$263,$A15,Mensal!$C$5:$C$263,5) | G15: =SUMIFS(Mensal!$H$5:$H$263,Mensal!$B$5:$B$263,$A15,Mensal!$C$5:$C$263,6) | H15: =SUMIFS(Mensal!$H$5:$H$263,Mensal!$B$5:$B$263,$A15,Mensal!$C$5:$C$263,7) | I15: =SUMIFS(Mensal!$H$5:$H$263,Mensal!$B$5:$B$263,$A15,Mensal!$C$5:$C$263,8) | J15: =SUMIFS(Mensal!$H$5:$H$263,Mensal!$B$5:$B$263,$A15,Mensal!$C$5:$C$263,9) | K15: =SUMIFS(Mensal!$H$5:$H$263,Mensal!$B$5:$B$263,$A15,Mensal!$C$5:$C$263,10) | L15: =SUMIFS(Mensal!$H$5:$H$263,Mensal!$B$5:$B$263,$A15,Mensal!$C$5:$C$263,11) | M15: =SUMIFS(Mensal!$H$5:$H$263,Mensal!$B$5:$B$263,$A15,Mensal!$C$5:$C$263,12) | N15: =SUM(B15:M15)
... A25: 2026 | B25: =SUMIFS(Mensal!$H$5:$H$263,Mensal!$B$5:$B$263,$A25,Mensal!$C$5:$C$263,1) | C25: =SUMIFS(Mensal!$H$5:$H$263,Mensal!$B$5:$B$263,$A25,Mensal!$C$5:$C$263,2) | D25: =SUMIFS(Mensal!$H$5:$H$263,Mensal!$B$5:$B$263,$A25,Mensal!$C$5:$C$263,3) | E25: =SUMIFS(Mensal!$H$5:$H$263,Mensal!$B$5:$B$263,$A25,Mensal!$C$5:$C$263,4) | F25: =SUMIFS(Mensal!$H$5:$H$263,Mensal!$B$5:$B$263,$A25,Mensal!$C$5:$C$263,5) | G25: =SUMIFS(Mensal!$H$5:$H$263,Mensal!$B$5:$B$263,$A25,Mensal!$C$5:$C$263,6) | H25: =SUMIFS(Mensal!$H$5:$H$263,Mensal!$B$5:$B$263,$A25,Mensal!$C$5:$C$263,7) | I25: =SUMIFS(Mensal!$H$5:$H$263,Mensal!$B$5:$B$263,$A25,Mensal!$C$5:$C$263,8) | J25: =SUMIFS(Mensal!$H$5:$H$263,Mensal!$B$5:$B$263,$A25,Mensal!$C$5:$C$263,9) | K25: =SUMIFS(Mensal!$H$5:$H$263,Mensal!$B$5:$B$263,$A25,Mensal!$C$5:$C$263,10) | L25: =SUMIFS(Mensal!$H$5:$H$263,Mensal!$B$5:$B$263,$A25,Mensal!$C$5:$C$263,11) | M25: =SUMIFS(Mensal!$H$5:$H$263,Mensal!$B$5:$B$263,$A25,Mensal!$C$5:$C$263,12) | N25: =SUM(B25:M25)
A26: TOTAL | B26: =SUM(B4:B25) | C26: =SUM(C4:C25) | D26: =SUM(D4:D25) | E26: =SUM(E4:E25) | F26: =SUM(F4:F25) | G26: =SUM(G4:G25) | H26: =SUM(H4:H25) | I26: =SUM(I4:I25) | ... N26: =SUM(N4:N25)
A28: Inclui meses ESTIMADOS: 2007 (2008 ÷ IPCA) e out/2010–dez/2011, fev/2013–mai/2017 (média com variação). Ver aba Estimativas.

Sheet Distrato
A1: Simulação de distrato - Lei 4.886/65 (representante comercial)
A3: Premissas
A4: Início do Cenário B (competência) | B4: 44378 | C4: Premissa: distrato de R$ 93.000 pago abr-jun/2021 teria quitado o período anterior. Altere se necessário.
A5: Último mês considerado | B5: 46204 | C5: Última competência paga (título 174, pago 17/08/2026).
A7: Cenário A - todo o período disponível
A8: Base: total comissão (real + estimado) | B8: =Mensal!H264
A9: Indenização (1/12 - art. 27, "j") | B9: =B8/12
A10: Aviso prévio (1/3 das comissões dos últimos 3 meses - art. 34) | B10: =B17
A11: TOTAL Cenário A | B11: =B9+B10
A13: Cenário B - a partir do início informado em B4
A14: Base: total comissão + prêmio | B14: =SUMIFS(Mensal!$H$5:$H$263,Mensal!$A$5:$A$263,">="&B4,Mensal!$A$5:$A$263,"<="&B5)
A15: Indenização (1/12) | B15: =B14/12
A16: Soma dos últimos 3 meses | B16: =SUMIFS(Mensal!$H$5:$H$263,Mensal!$A$5:$A$263,">="&DATE(YEAR(B5),MONTH(B5)-2,1),Mensal!$A$5:$A$263,"<="&B5)
A17: Aviso prévio (1/3) | B17: =B16/3
A18: TOTAL Cenário B | B18: =B15+B17
A20: Células amarelas são premissas editáveis. Valores sem correção monetária. Conferir com o jurídico/contador.

Sheet Estimativas
A1: Estimativas para meses sem dado (valores NÃO reais - usar com transparência no distrato)
A3: IPCA 2008 (IBGE) | B3: 0.059 | C3: Fonte: IBGE, IPCA acumulado 2008 = 5,90%. Usado para deflacionar 2008 e estimar 2007.
A4: Variação aleatória máxima (±) | B4: 0.15 | C4: Fatores gerados uma única vez (semente 2026) e gravados na coluna E; editáveis.
A6: Média real out/2009–set/2010 | B6: =SUMIFS(Mensal!$F$5:$F$263,Mensal!$A$5:$A$263,">="&DATE(2009,10,1),Mensal!$A$5:$A$263,"<="&DATE(2010,9,1))/12 | C6: Âncora antes do buraco out/2010–dez/2011
A7: Média real jan–dez/2012 | B7: =SUMIFS(Mensal!$F$5:$F$263,Mensal!$A$5:$A$263,">="&DATE(2012,1,1),Mensal!$A$5:$A$263,"<="&DATE(2012,12,1))/12 | C7: Âncora depois do buraco out/2010–dez/2011
A8: Média real fev/2012–jan/2013 | B8: =SUMIFS(Mensal!$F$5:$F$263,Mensal!$A$5:$A$263,">="&DATE(2012,2,1),Mensal!$A$5:$A$263,"<="&DATE(2013,1,1))/12 | C8: Âncora antes do buraco fev/2013–mai/2017
A9: Média real jun/2017–mai/2018 | B9: =SUMIFS(Mensal!$F$5:$F$263,Mensal!$A$5:$A$263,">="&DATE(2017,6,1),Mensal!$A$5:$A$263,"<="&DATE(2018,5,1))/12 | C9: Âncora depois do buraco fev/2013–mai/2017 (contas a pagar = total pago à Frugis)
A11: Competência | B11: Grupo | C11: Método | D11: Base | E11: Fator aleatório | F11: Valor estimado
A12: 39083 | B12: 2007 | C12: Mesmo mês de 2008 ÷ (1+IPCA 2008) | D12: =SUMIFS(Mensal!$F$5:$F$263,Mensal!$A$5:$A$263,DATE(YEAR(A12)+1,MONTH(A12),1))/(1+$B$3) | E12: 1 | F12: =ROUND(D12*E12,2)
A13: 39114 | B13: 2007 | C13: Mesmo mês de 2008 ÷ (1+IPCA 2008) | D13: =SUMIFS(Mensal!$F$5:$F$263,Mensal!$A$5:$A$263,DATE(YEAR(A13)+1,MONTH(A13),1))/(1+$B$3) | E13: 1 | F13: =ROUND(D13*E13,2)
A14: 39142 | B14: 2007 | C14: Mesmo mês de 2008 ÷ (1+IPCA 2008) | D14: =SUMIFS(Mensal!$F$5:$F$263,Mensal!$A$5:$A$263,DATE(YEAR(A14)+1,MONTH(A14),1))/(1+$B$3) | E14: 1 | F14: =ROUND(D14*E14,2)
A15: 39173 | B15: 2007 | C15: Mesmo mês de 2008 ÷ (1+IPCA 2008) | D15: =SUMIFS(Mensal!$F$5:$F$263,Mensal!$A$5:$A$263,DATE(YEAR(A15)+1,MONTH(A15),1))/(1+$B$3) | E15: 1 | F15: =ROUND(D15*E15,2)
A16: 39203 | B16: 2007 | C16: Mesmo mês de 2008 ÷ (1+IPCA 2008) | D16: =SUMIFS(Mensal!$F$5:$F$263,Mensal!$A$5:$A$263,DATE(YEAR(A16)+1,MONTH(A16),1))/(1+$B$3) | E16: 1 | F16: =ROUND(D16*E16,2)
A17: 39234 | B17: 2007 | C17: Mesmo mês de 2008 ÷ (1+IPCA 2008) | D17: =SUMIFS(Mensal!$F$5:$F$263,Mensal!$A$5:$A$263,DATE(YEAR(A17)+1,MONTH(A17),1))/(1+$B$3) | E17: 1 | F17: =ROUND(D17*E17,2)
A18: 39264 | B18: 2007 | C18: Mesmo mês de 2008 ÷ (1+IPCA 2008) | D18: =SUMIFS(Mensal!$F$5:$F$263,Mensal!$A$5:$A$263,DATE(YEAR(A18)+1,MONTH(A18),1))/(1+$B$3) | E18: 1 | F18: =ROUND(D18*E18,2)
A19: 39295 | B19: 2007 | C19: Mesmo mês de 2008 ÷ (1+IPCA 2008) | D19: =SUMIFS(Mensal!$F$5:$F$263,Mensal!$A$5:$A$263,DATE(YEAR(A19)+1,MONTH(A19),1))/(1+$B$3) | E19: 1 | F19: =ROUND(D19*E19,2)
A20: 39326 | B20: 2007 | C20: Mesmo mês de 2008 ÷ (1+IPCA 2008) | D20: =SUMIFS(Mensal!$F$5:$F$263,Mensal!$A$5:$A$263,DATE(YEAR(A20)+1,MONTH(A20),1))/(1+$B$3) | E20: 1 | F20: =ROUND(D20*E20,2)
A21: 39356 | B21: 2007 | C21: Mesmo mês de 2008 ÷ (1+IPCA 2008) | D21: =SUMIFS(Mensal!$F$5:$F$263,Mensal!$A$5:$A$263,DATE(YEAR(A21)+1,MONTH(A21),1))/(1+$B$3) | E21: 1 | F21: =ROUND(D21*E21,2)
A22: 39387 | B22: 2007 | C22: Mesmo mês de 2008 ÷ (1+IPCA 2008) | D22: =SUMIFS(Mensal!$F$5:$F$263,Mensal!$A$5:$A$263,DATE(YEAR(A22)+1,MONTH(A22),1))/(1+$B$3) | E22: 1 | F22: =ROUND(D22*E22,2)
A23: 39417 | B23: 2007 | C23: Mesmo mês de 2008 ÷ (1+IPCA 2008) | D23: =SUMIFS(Mensal!$F$5:$F$263,Mensal!$A$5:$A$263,DATE(YEAR(A23)+1,MONTH(A23),1))/(1+$B$3) | E23: 1 | F23: =ROUND(D23*E23,2)
A24: 40452 | B24: out/2010–dez/2011 | C24: Interpolação linear entre as médias vizinhas × fator aleatório (soma do grupo preservada) | D24: =$B$6+($B$7-$B$6)*1/16 | E24: 0.8857 | F24: =ROUND(D24*E24*SUM($D$24:$D$38)/SUMPRODUCT($D$24:$D$38,$E$24:$E$38),2)
A25: 40483 | B25: out/2010–dez/2011 | C25: Interpolação linear entre as médias vizinhas × fator aleatório (soma do grupo preservada) | D25: =$B$6+($B$7-$B$6)*2/16 | E25: 1.0008 | F25: =ROUND(D25*E25*SUM($D$24:$D$38)/SUMPRODUCT($D$24:$D$38,$E$24:$E$38),2)
A26: 40513 | B26: out/2010–dez/2011 | C26: Interpolação linear entre as médias vizinhas × fator aleatório (soma do grupo preservada) | D26: =$B$6+($B$7-$B$6)*3/16 | E26: 1.0035 | F26: =ROUND(D26*E26*SUM($D$24:$D$38)/SUMPRODUCT($D$24:$D$38,$E$24:$E$38),2)
A27: 40544 | B27: out/2010–dez/2011 | C27: Interpolação linear entre as médias vizinhas × fator aleatório (soma do grupo preservada) | D27: =$B$6+($B$7-$B$6)*4/16 | E27: 1.108 | F27: =ROUND(D27*E27*SUM($D$24:$D$38)/SUMPRODUCT($D$24:$D$38,$E$24:$E$38),2)
A28: 40575 | B28: out/2010–dez/2011 | C28: Interpolação linear entre as médias vizinhas × fator aleatório (soma do grupo preservada) | D28: =$B$6+($B$7-$B$6)*5/16 | E28: 0.8808 | F28: =ROUND(D28*E28*SUM($D$24:$D$38)/SUMPRODUCT($D$24:$D$38,$E$24:$E$38),2)
A29: 40603 | B29: out/2010–dez/2011 | C29: Interpolação linear entre as médias vizinhas × fator aleatório (soma do grupo preservada) | D29: =$B$6+($B$7-$B$6)*6/16 | E29: 0.917 | F29: =ROUND(D29*E29*SUM($D$24:$D$38)/SUMPRODUCT($D$24:$D$38,$E$24:$E$38),2)
A30: 40634 | B30: out/2010–dez/2011 | C30: Interpolação linear entre as médias vizinhas × fator aleatório (soma do grupo preservada) | D30: =$B$6+($B$7-$B$6)*7/16 | E30: 1.0303 | F30: =ROUND(D30*E30*SUM($D$24:$D$38)/SUMPRODUCT($D$24:$D$38,$E$24:$E$38),2)
A31: 40664 | B31: out/2010–dez/2011 | C31: Interpolação linear entre as médias vizinhas × fator aleatório (soma do grupo preservada) | D31: =$B$6+($B$7-$B$6)*8/16 | E31: 1.017 | F31: =ROUND(D31*E31*SUM($D$24:$D$38)/SUMPRODUCT($D$24:$D$38,$E$24:$E$38),2)
A32: 40695 | B32: out/2010–dez/2011 | C32: Interpolação linear entre as médias vizinhas × fator aleatório (soma do grupo preservada) | D32: =$B$6+($B$7-$B$6)*9/16 | E32: 1.085 | F32: =ROUND(D32*E32*SUM($D$24:$D$38)/SUMPRODUCT($D$24:$D$38,$E$24:$E$38),2)
A33: 40725 | B33: out/2010–dez/2011 | C33: Interpolação linear entre as médias vizinhas × fator aleatório (soma do grupo preservada) | D33: =$B$6+($B$7-$B$6)*10/16 | E33: 1.0143 | F33: =ROUND(D33*E33*SUM($D$24:$D$38)/SUMPRODUCT($D$24:$D$38,$E$24:$E$38),2)
A34: 40756 | B34: out/2010–dez/2011 | C34: Interpolação linear entre as médias vizinhas × fator aleatório (soma do grupo preservada) | D34: =$B$6+($B$7-$B$6)*11/16 | E34: 1.0692 | F34: =ROUND(D34*E34*SUM($D$24:$D$38)/SUMPRODUCT($D$24:$D$38,$E$24:$E$38),2)
A35: 40787 | B35: out/2010–dez/2011 | C35: Interpolação linear entre as médias vizinhas × fator aleatório (soma do grupo preservada) | D35: =$B$6+($B$7-$B$6)*12/16 | E35: 1.0804 | F35: =ROUND(D35*E35*SUM($D$24:$D$38)/SUMPRODUCT($D$24:$D$38,$E$24:$E$38),2)
A36: 40817 | B36: out/2010–dez/2011 | C36: Interpolação linear entre as médias vizinhas × fator aleatório (soma do grupo preservada) | D36: =$B$6+($B$7-$B$6)*13/16 | E36: 1.0753 | F36: =ROUND(D36*E36*SUM($D$24:$D$38)/SUMPRODUCT($D$24:$D$38,$E$24:$E$38),2)
A37: 40848 | B37: out/2010–dez/2011 | C37: Interpolação linear entre as médias vizinhas × fator aleatório (soma do grupo preservada) | D37: =$B$6+($B$7-$B$6)*14/16 | E37: 1.026 | F37: =ROUND(D37*E37*SUM($D$24:$D$38)/SUMPRODUCT($D$24:$D$38,$E$24:$E$38),2)
A38: 40878 | B38: out/2010–dez/2011 | C38: Interpolação linear entre as médias vizinhas × fator aleatório (soma do grupo preservada) | D38: =$B$6+($B$7-$B$6)*15/16 | E38: 0.922 | F38: =ROUND(D38*E38*SUM($D$24:$D$38)/SUMPRODUCT($D$24:$D$38,$E$24:$E$38),2)
A39: 41306 | B39: fev/2013–mai/2017 | C39: Interpolação linear entre as médias vizinhas × fator aleatório (soma do grupo preservada) | D39: =$B$8+($B$9-$B$8)*1/53 | E39: 1.0343 | F39: =ROUND(D39*E39*SUM($D$39:$D$90)/SUMPRODUCT($D$39:$D$90,$E$39:$E$90),2)
A40: 41334 | B40: fev/2013–mai/2017 | C40: Interpolação linear entre as médias vizinhas × fator aleatório (soma do grupo preservada) | D40: =$B$8+($B$9-$B$8)*2/53 | E40: 0.8832 | F40: =ROUND(D40*E40*SUM($D$39:$D$90)/SUMPRODUCT($D$39:$D$90,$E$39:$E$90),2)
A41: 41365 | B41: fev/2013–mai/2017 | C41: Interpolação linear entre as médias vizinhas × fator aleatório (soma do grupo preservada) | D41: =$B$8+($B$9-$B$8)*3/53 | E41: 1.095 | F41: =ROUND(D41*E41*SUM($D$39:$D$90)/SUMPRODUCT($D$39:$D$90,$E$39:$E$90),2)
A42: 41395 | B42: fev/2013–mai/2017 | C42: Interpolação linear entre as médias vizinhas × fator aleatório (soma do grupo preservada) | D42: =$B$8+($B$9-$B$8)*4/53 | E42: 0.9849 | F42: =ROUND(D42*E42*SUM($D$39:$D$90)/SUMPRODUCT($D$39:$D$90,$E$39:$E$90),2)
A43: 41426 | B43: fev/2013–mai/2017 | C43: Interpolação linear entre as médias vizinhas × fator aleatório (soma do grupo preservada) | D43: =$B$8+($B$9-$B$8)*5/53 | E43: 1.0944 | F43: =ROUND(D43*E43*SUM($D$39:$D$90)/SUMPRODUCT($D$39:$D$90,$E$39:$E$90),2)
...

Sheet Lancamentos
A1: Fonte | B1: Data (pagto / nota) | C1: Competência | D1: Ano | E1: Mês | F1: Título / Histórico | G1: Favorecido | H1: Tipo | I1: Valor bruto | J1: Desconto | K1: Valor líquido | L1: Base comissão
A2: Conta corrente MFRUGIS05.XLS | B2: 38365 | C2: 38353 | D2: =YEAR(C2) | E2: =MONTH(C2) | F2: DEV :TENDA ATACADO LTDA | G2: MARIO FRUGIS (01.04.01) | H2: DEVOLUCAO | I2: -2.13 | J2: 0 | K2: =I2-J2 | L2: =IF(H2="DISTRATO",0,I2)
A3: Conta corrente MFRUGIS05.XLS | B3: 38376 | C3: 38353 | D3: =YEAR(C3) | E3: =MONTH(C3) | F3: 40306 NFV :TENDA ATACADO LTDA | G3: MARIO FRUGIS (01.04.01) | H3: NFV | I3: 200.84 | J3: 0 | K3: =I3-J3 | L3: =IF(H3="DISTRATO",0,I3)
A4: Conta corrente MFRUGIS05.XLS | B4: 38383 | C4: 38353 | D4: =YEAR(C4) | E4: =MONTH(C4) | F4: 40328 NFV :TENDA ATACADO LTDA | G4: MARIO FRUGIS (01.04.01) | H4: NFV | I4: 255.21 | J4: 0 | K4: =I4-J4 | L4: =IF(H4="DISTRATO",0,I4)
A5: Conta corrente MFRUGIS05.XLS | B5: 38383 | C5: 38353 | D5: =YEAR(C5) | E5: =MONTH(C5) | F5: 40328 NFV :TENDA ATACADO LTDA | G5: MARIO FRUGIS (01.04.01) | H5: NFV | I5: 148.28 | J5: 0 | K5: =I5-J5 | L5: =IF(H5="DISTRATO",0,I5)
A6: Conta corrente MFRUGIS05.XLS | B6: 38394 | C6: 38384 | D6: =YEAR(C6) | E6: =MONTH(C6) | F6: DEV :TENDA ATACADO LTDA | G6: MARIO FRUGIS (01.04.01) | H6: DEVOLUCAO | I6: -0.52 | J6: 0 | K6: =I6-J6 | L6: =IF(H6="DISTRATO",0,I6)
A7: Conta corrente MFRUGIS05.XLS | B7: 38405 | C7: 38384 | D7: =YEAR(C7) | E7: =MONTH(C7) | F7: 27524 NFV :TENDA ATACADO LTDA | G7: MARIO FRUGIS (01.04.01) | H7: NFV | I7: 147.84 | J7: 0 | K7: =I7-J7 | L7: =IF(H7="DISTRATO",0,I7)
A8: Conta corrente MFRUGIS05.XLS | B8: 38411 | C8: 38384 | D8: =YEAR(C8) | E8: =MONTH(C8) | F8: 27540 NFV :TENDA ATACADO LTDA | G8: MARIO FRUGIS (01.04.01) | H8: NFV | I8: 70.06 | J8: 0 | K8: =I8-J8 | L8: =IF(H8="DISTRATO",0,I8)
A9: Conta corrente MFRUGIS05.XLS | B9: 38425 | C9: 38412 | D9: =YEAR(C9) | E9: =MONTH(C9) | F9: 1605 NFV :TENDA ATACADO LTDA | G9: MARIO FRUGIS (01.04.01) | H9: NFV | I9: 159.17 | J9: 0 | K9: =I9-J9 | L9: =IF(H9="DISTRATO",0,I9)
A10: Conta corrente MFRUGIS05.XLS | B10: 38428 | C10: 38412 | D10: =YEAR(C10) | E10: =MONTH(C10) | F10: 1622 NFV :TENDA ATACADO LTDA | G10: MARIO FRUGIS (01.04.01) | H10: NFV | I10: 62.92 | J10: 0 | K10: =I10-J10 | L10: =IF(H10="DISTRATO",0,I10)
A11: Conta corrente MFRUGIS05.XLS | B11: 38428 | C11: 38412 | D11: =YEAR(C11) | E11: =MONTH(C11) | F11: 1623 NFV :TENDA ATACADO LTDA | G11: MARIO FRUGIS (01.04.01) | H11: NFV | I11: 62.92 | J11: 0 | K11: =I11-J11 | L11: =IF(H11="DISTRATO",0,I11)
A12: Conta corrente MFRUGIS05.XLS | B12: 38434 | C12: 38412 | D12: =YEAR(C12) | E12: =MONTH(C12) | F12: DEV :TENDA ATACADO LTDA | G12: MARIO FRUGIS (01.04.01) | H12: DEVOLUCAO | I12: -1.32 | J12: 0 | K12: =I12-J12 | L12: =IF(H12="DISTRATO",0,I12)
A13: Conta corrente MFRUGIS05.XLS | B13: 38439 | C13: 38412 | D13: =YEAR(C13) | E13: =MONTH(C13) | F13: 1594 NFV :TENDA ATACADO LTDA | G13: MARIO FRUGIS (01.04.01) | H13: NFV | I13: 62.92 | J13: 0 | K13: =I13-J13 | L13: =IF(H13="DISTRATO",0,I13)
... A2342: Contas a pagar - aba Comissões | B2342: 46251 | C2342: 46204 | D2342: =YEAR(C2342) | E2342: =MONTH(C2342) | F2342: 174 | G2342: FRUGIS REPRESENTACOES LTDA (CNPJ 11.989.186/0001-70) | H2342: COMISSAO | I2342: 5734.34 | J2342: 0 | K2342: =I2342-J2342 | L2342: =IF(H2342="DISTRATO",0,I2342)
A2343: TOTAL | I2343: =SUM(I2:I2342) | J2343: =SUM(J2:J2342) | K2343: =SUM(K2:K2342) | L2343: =SUM(L2:L2342)

Sheet ContaCorrente
A1: Competência | B1: Crédito | C1: Débito | D1: Saldo | F1: Resumo mensal dos extratos "Conta Corrente dos Representantes" (MFRUGIS05/06/08/09/10/11 e FRUGIS5) - todos os clientes, não só Tenda. Soma de cada arquivo confere com o "Saldo do Periodo" impresso.
A2: 38353 | B2: 2248.38 | C2: 68.48 | D2: =B2-C2
A3: 38384 | B3: 2392.27 | C3: 33.02 | D3: =B3-C3
A4: 38412 | B4: 2607.86 | C4: 42.46 | D4: =B4-C4
A5: 38443 | B5: 2441.81 | C5: 5.74 | D5: =B5-C5
A6: 38473 | B6: 2817.47 | C6: 155.27 | D6: =B6-C6
A7: 38504 | B7: 2628.11 | C7: 192.12 | D7: =B7-C7
A8: 38534 | B8: 2114.75 | C8: 64.63 | D8: =B8-C8
A9: 38565 | B9: 3558.34 | C9: 869.3 | D9: =B9-C9
A10: 38596 | B10: 2589.09 | C10: 221.78 | D10: =B10-C10
A11: 38626 | B11: 2511.8 | C11: 35.63 | D11: =B11-C11
A12: 38657 | B12: 2726 | C12: 236.73 | D12: =B12-C12
A13: 38687 | B13: 2690.08 | C13: 290.56 | D13: =B13-C13
... A76: 41275 | B76: 8108.42 | C76: 596.01 | D76: =B76-C76
A77: TOTAL | B77: =SUM(B2:B76) | C77: =SUM(C2:C76) | D77: =SUM(D2:D76)

Sheet Notas
A1: FONTES
A2: 1) Extratos "Conta Corrente dos Representantes" enviados (TOTAL QUIMICA / TOTAL CENTRO DE DISTR. INTEGRADA, representante 01.04.01-MARIO): MFRUGIS05, 06, 08, 09, 10, 11 e FRUGIS5 (2012 + jan/2013). Somente lançamentos com "TENDA" no histórico entram na comissão Tenda 2005-2013.
A3: Conferência: a soma de cada extrato bate com o "Saldo do Periodo" impresso. Tenda set/2008 a set/2010 bate centavo por centavo com a aba Detalhamento de Comissoes_Tenda_Resumo_e_Detalhamento.xlsx.
A4: FRUGIS1 (2012) e FRUGIS2 (jan/2013) são idênticos, linha a linha, ao FRUGIS5 — usado só o FRUGIS5 para não duplicar. FRUGIS.XLS (2011) só tem notas do Roldão, sem Tenda.
A5: 2) Contas a pagar, aba "Comissões" (ERP_Base Comissão 2026.xlsx): pagamentos à FRUGIS REPRESENTACOES LTDA e a MARIO P. FRUGIS, jun/2017 a ago/2026. Soma líquida bate com a aba "Dinamica (4)" do arquivo "21 - 12 Base para Calcular Distrato Comissoes 2026.xlsx".
A6: 3) Planilhas mensais com o código 01.07.03 (MARIO - TENDA): JANEIRO 2023 = 22.738,21 e Maio 2026 = 3.009,10 — batem com os pagamentos, confirmando a regra de competência.
A8: REGRAS
A9: - 2005 a jan/2013: comissão Tenda = NFV + BONIF (negativa) - DEV - DESC, pelo mês da nota. Linhas iguais no extrato foram mantidas (o saldo impresso as inclui).
A10: - 2008: "DIF PERCENTUAL"/"DIFERENCA" mensal (R$ 14.956,91) incluído como Tenda: acompanha a comissão do Tenda (≈ 82-88% dela na maioria dos meses) e some em 2009, quando a comissão do Tenda sobe — indica correção do % do Tenda feita à mão em 2008.
A11: - 2009: "DIFERENCA" não segue o Tenda; entrou só a parte proporcional à participação do Tenda na comissão de cada mês (rateio, R$ 1.022,26).
A12: - Jun/2017 em diante: competência = mês anterior ao pagamento; valor bruto antes de descontos; distratos já pagos (2020 e 2021) fora da base.
A14: ESTIMATIVAS (pedido do usuário)
... A22: - De jun/2017 em diante o valor é o total pago à Frugis. O código 01.07.03 (MARIO - TENDA) indica ser só Tenda, mas os extratos antigos mostram que ele também vendia para outros clientes — confirmar.
